<robot name="ICUB_2-5_BB_SIM_MODEL">
  <link name="root_link">
    <inertial>
      <origin xyz="0.0248821 0.000103947 -0.0440806" rpy="1.5707963267948961 0 -1.5707963267948961"/>
      <mass value="5.09143"/>
      <inertia ixx="0.0139679" ixy="-5.93488e-06" ixz="-1.55458e-05" iyy="0.0202112" iyz="-0.00170968" izz="0.0249124"/>
    </inertial>
    <visual>
      <origin xyz="-0.0364 0 0.032" rpy="1.5707963267948961 0 -1.5707963267948961"/>
      <geometry>
        <mesh filename="package://iCub/meshes/simmechanics/sim_sea_2-5_root_link_prt-binary.stl" scale="0.001 0.001 0.001"/>
      </geometry>
      <material name="green">
        <color rgba="0 1 0 1"/>
      </material>
    </visual>
    <collision>
      <origin xyz="-0.0364 0 0.032" rpy="1.5707963267948961 0 -1.5707963267948961"/>
      <geometry>
        <mesh filename="package://iCub/meshes/simmechanics/sim_sea_2-5_root_link_prt-binary.stl" scale="0.001 0.001 0.001"/>
      </geometry>
    </collision>
  </link>
  <link name="root_link_ems_acc_eb5"/>
  <joint name="root_link_ems_acc_eb5_fixed_joint" type="fixed">
    <origin xyz="0.0493308 -0.0125771 -0.115691" rpy="3.141592653589793 1.2915440450258349 3.141592653589793"/>
    <parent link="root_link"/>
    <child link="root_link_ems_acc_eb5"/>
    <dynamics damping="0.1"/>
  </joint>
  <link name="root_link_ems_gyro_eb5"/>
  <joint name="root_link_ems_gyro_eb5_fixed_joint" type="fixed">
    <origin xyz="0.0493308 -0.0125771 -0.115691" rpy="3.141592653589793 1.2915440450258349 3.141592653589793"/>
    <parent link="root_link"/>
    <child link="root_link_ems_gyro_eb5"/>
    <dynamics damping="0.1"/>
  </joint>
  <link name="torso_1">
    <inertial>
      <origin xyz="0.0270921359 0.02914798 -0.0004398" rpy="0 0 0"/>
      <mass value="0.67144"/>
      <inertia ixx="0.00040911" ixy="-1.04522e-06" ixz="-1.02516e-06" iyy="0.000384141" iyz="6.50708e-06" izz="0.000299445"/>
    </inertial>
    <visual>
      <origin xyz="0.0270462998093 0.032 0.0364" rpy="0 0 0"/>
      <geometry>
        <mesh filename="package://iCub/meshes/simmechanics/sim_sea_2-5_lap_belt_1_prt-binary.stl" scale="0.001 0.001 0.001"/>
      </geometry>
      <material name="black">
        <color rgba="0 0 0 1"/>
      </material>
    </visual>
    <collision>
      <origin xyz="0.0270462998093 0.032 0.0364" rpy="0 0 0"/>
      <geometry>
        <mesh filename="package://iCub/meshes/simmechanics/sim_sea_2-5_lap_belt_1_prt-binary.stl" scale="0.001 0.001 0.001"/>
      </geometry>
    </collision>
  </link>
  <joint name="torso_pitch" type="revolute">
    <origin xyz="0 0.0270463 0" rpy="1.5707963267948961 0 -1.5707963267948961"/>
    <axis xyz="1.0 0.0 0.0"/>
    <parent link="root_link"/>
    <child link="torso_1"/>
    <limit effort="50000" lower="-0.3490658503988659" upper="1.2217304763960306" velocity="50000"/>
    <dynamics damping="0.06"/>
  </joint>
  <link name="torso_2">
    <inertial>
      <origin xyz="-0.000113507809265 0.0361525 0.0570963" rpy="0 0 0"/>
      <mass value="0.425685"/>
      <inertia ixx="0.000829234" ixy="2.37006e-08" ixz="9.25231e-08" iyy="0.000436517" iyz="-1.74814e-07" izz="0.000604802"/>
    </inertial>
    <visual>
      <origin xyz="0 0.1433 0.0386531" rpy="0 0 0"/>
      <geometry>
        <mesh filename="package://iCub/meshes/simmechanics/sim_sea_2-5_lap_belt_2_prt-binary.stl" scale="0.001 0.001 0.001"/>
      </geometry>
      <material name="red">
        <color rgba="1 0 0 1"/>
      </material>
    </visual>
    <collision>
      <origin xyz="0 0.1433 0.0386531" rpy="0 0 0"/>
      <geometry>
        <mesh filename="package://iCub/meshes/simmechanics/sim_sea_2-5_lap_belt_2_prt-binary.stl" scale="0.001 0.001 0.001"/>
      </geometry>
    </collision>
  </link>
  <joint name="torso_roll" type="revolute">
    <origin xyz="0.0270462998093 0.032 -0.0573446" rpy="0 0 0"/>
    <axis xyz="0.0 0.0 -1.0"/>
    <parent link="torso_1"/>
    <child link="torso_2"/>
    <limit effort="50000" lower="-0.5235987755982988" upper="0.5235987755982988" velocity="50000"/>
    <dynamics damping="0.06"/>
  </joint>
  <link name="chest">
    <inertial>
      <origin xyz="0.000188619190735 0.073091 -0.0472381" rpy="0 0 0"/>
      <mass value="7.638"/>
      <inertia ixx="0.043032487861801666" ixy="2.9107538880437883e-05" ixz="0.00018198522994852988" iyy="0.04408357255482159" iyz="-0.0004291064091076428" izz="0.026056324991143805"/>
    </inertial>
    <visual>
      <origin xyz="0 0.0928 -0.024189" rpy="0 0 0"/>
      <geometry>
        <mesh filename="package://iCub/meshes/simmechanics/sim_sea_2-5_chest_bb_prt-binary.stl" scale="0.001 0.001 0.001"/>
      </geometry>
      <material name="blue">
        <color rgba="0 0 1 1"/>
      </material>
    </visual>
    <collision>
      <origin xyz="0 0.0928 -0.024189" rpy="0 0 0"/>
      <geometry>
        <mesh filename="package://iCub/meshes/simmechanics/sim_sea_2-5_chest_bb_prt-binary.stl" scale="0.001 0.001 0.001"/>
      </geometry>
    </collision>
  </link>
  <joint name="torso_yaw" type="revolute">
    <origin xyz="0 0.05 0.0628421" rpy="0 0 0"/>
    <axis xyz="0.0 -1.0 0.0"/>
    <parent link="torso_2"/>
    <child link="chest"/>
    <limit effort="50000" lower="-0.8726646259971648" upper="0.8726646259971648" velocity="50000"/>
    <dynamics damping="0.06"/>
  </joint>
  <link name="chest_ems_acc_eb1"/>
  <joint name="chest_ems_acc_eb1_fixed_joint" type="fixed">
    <origin xyz="0.0647855001907 0.064043 -0.0647091" rpy="3.1415169122972952 -0.2617993091222473 0.0002926418802545251"/>
    <parent link="chest"/>
    <child link="chest_ems_acc_eb1"/>
    <dynamics damping="0.1"/>
  </joint>
  <link name="chest_ems_gyro_eb1"/>
  <joint name="chest_ems_gyro_eb1_fixed_joint" type="fixed">
    <origin xyz="0.0692016001907 0.064548 -0.0635258" rpy="3.1415169122972952 -0.2617993091222473 0.0002926418802545251"/>
    <parent link="chest"/>
    <child link="chest_ems_gyro_eb1"/>
    <dynamics damping="0.1"/>
  </joint>
  <link name="chest_ems_acc_eb2"/>
  <joint name="chest_ems_acc_eb2_fixed_joint" type="fixed">
    <origin xyz="0.0204533001907 0.088063 -0.0641645" rpy="3.141590501042822 0.2617993198185103 3.1415843367812997"/>
    <parent link="chest"/>
    <child link="chest_ems_acc_eb2"/>
    <dynamics damping="0.1"/>
  </joint>
  <link name="chest_ems_gyro_eb2"/>
  <joint name="chest_ems_gyro_eb2_fixed_joint" type="fixed">
    <origin xyz="0.0160371001907 0.087559 -0.0653479" rpy="3.141590501042822 0.2617993198185103 3.1415843367812997"/>
    <parent link="chest"/>
    <child link="chest_ems_gyro_eb2"/>
    <dynamics damping="0.1"/>
  </joint>
  <link name="chest_ems_acc_eb3"/>
  <joint name="chest_ems_acc_eb3_fixed_joint" type="fixed">
    <origin xyz="-0.0230587998093 0.064019 -0.0758985" rpy="3.141109162025268 0.26110051647116095 -0.00030907146255546275"/>
    <parent link="chest"/>
    <child link="chest_ems_acc_eb3"/>
    <dynamics damping="0.1"/>
  </joint>
  <link name="chest_ems_gyro_eb3"/>
  <joint name="chest_ems_gyro_eb3_fixed_joint" type="fixed">
    <origin xyz="-0.0186416998093 0.064521 -0.0770785" rpy="3.141109162025268 0.26110051647116095 -0.00030907146255546275"/>
    <parent link="chest"/>
    <child link="chest_ems_gyro_eb3"/>
    <dynamics damping="0.1"/>
  </joint>
  <link name="chest_ems_acc_eb4"/>
  <joint name="chest_ems_acc_eb4_fixed_joint" type="fixed">
    <origin xyz="-0.0621620998093 0.088063 -0.0529887" rpy="-3.1415905047625503 -0.26179931981852844 3.141584339870295"/>
    <parent link="chest"/>
    <child link="chest_ems_acc_eb4"/>
    <dynamics damping="0.1"/>
  </joint>
  <link name="chest_ems_gyro_eb4"/>
  <joint name="chest_ems_gyro_eb4_fixed_joint" type="fixed">
    <origin xyz="-0.0665783998093 0.087559 -0.0518054" rpy="-3.1415905047625503 -0.26179931981852844 3.141584339870295"/>
    <parent link="chest"/>
    <child link="chest_ems_gyro_eb4"/>
    <dynamics damping="0.1"/>
  </joint>
  <link name="chest_mtb_acc_0b7"/>
  <joint name="chest_mtb_acc_0b7_fixed_joint" type="fixed">
    <origin xyz="-0.0607539998093 -0.0017836 0.0442341" rpy="0.8751677714915176 0.11636373439232421 -1.485973502467595"/>
    <parent link="chest"/>
    <child link="chest_mtb_acc_0b7"/>
    <dynamics damping="0.1"/>
  </joint>
  <link name="chest_mtb_acc_0b8"/>
  <joint name="chest_mtb_acc_0b8_fixed_joint" type="fixed">
    <origin xyz="-0.0457046998093 -0.001846 0.0567427" rpy="0.5009600846888737 0.10731368898312443 -1.4778325291042227"/>
    <parent link="chest"/>
    <child link="chest_mtb_acc_0b8"/>
    <dynamics damping="0.1"/>
  </joint>
  <link name="chest_mtb_acc_0b9"/>
  <joint name="chest_mtb_acc_0b9_fixed_joint" type="fixed">
    <origin xyz="0.0439036001907 -0.0017841 0.0577221" rpy="-0.5009599289728344 0.10731540424780756 -1.663760174692588"/>
    <parent link="chest"/>
    <child link="chest_mtb_acc_0b9"/>
    <dynamics damping="0.1"/>
  </joint>
  <link name="chest_mtb_acc_0b10"/>
  <joint name="chest_mtb_acc_0b10_fixed_joint" type="fixed">
    <origin xyz="0.0594286001907 -0.0018543 0.0457981" rpy="-0.8751681534754429 0.11636202547856214 -1.655618075051111"/>
    <parent link="chest"/>
    <child link="chest_mtb_acc_0b10"/>
    <dynamics damping="0.1"/>
  </joint>
  <link name="neck_1">
    <inertial>
      <origin xyz="0.0143705608 0.006567 -0.0063842" rpy="0 0 0"/>
      <mass value="0.125793"/>
      <inertia ixx="4.0647e-05" ixy="8.09156e-08" ixz="-3.74998e-08" iyy="3.881e-05" iyz="9.39717e-06" izz="4.7535e-05"/>
    </inertial>
    <visual>
      <origin xyz="0.0142999998093 -0.079997 -0.0295008" rpy="0 0 0"/>
      <geometry>
        <mesh filename="package://iCub/meshes/simmechanics/sim_sea_2-5_neck_1_prt-binary.stl" scale="0.001 0.001 0.001"/>
      </geometry>
      <material name="yellow">
        <color rgba="1 1 0 1"/>
      </material>
    </visual>
    <collision>
      <origin xyz="0.0142999998093 -0.079997 -0.0295008" rpy="0 0 0"/>
      <geometry>
        <mesh filename="package://iCub/meshes/simmechanics/sim_sea_2-5_neck_1_prt-binary.stl" scale="0.001 0.001 0.001"/>
      </geometry>
    </collision>
  </link>
  <joint name="neck_pitch" type="revolute">
    <origin xyz="-0.0142999998093 0.172797 0.0053118" rpy="0 0 0"/>
    <axis xyz="-1.0 0.0 0.0"/>
    <parent link="chest"/>
    <child link="neck_1"/>
    <limit effort="50000" lower="-0.6981317007977318" upper="0.3839724354387525" velocity="50000"/>
    <dynamics damping="0.06"/>
  </joint>
  <link name="neck_2">
    <inertial>
      <origin xyz="-8.8573009265e-05 0.035225 -0.01954527" rpy="0 0 0"/>
      <mass value="0.177087"/>
      <inertia ixx="0.000117943" ixy="-5.25591e-07" ixz="4.68307e-07" iyy="4.04013e-05" iyz="9.81476e-06" izz="0.000105186"/>
    </inertial>
    <visual>
      <origin xyz="0 -0.089497 -0.05030077" rpy="0 0 0"/>
      <geometry>
        <mesh filename="package://iCub/meshes/simmechanics/sim_sea_2-5_neck_2_prt-binary.stl" scale="0.001 0.001 0.001"/>
      </geometry>
      <material name="pink">
        <color rgba="1 0 1 1"/>
      </material>
    </visual>
    <collision>
      <origin xyz="0 -0.089497 -0.05030077" rpy="0 0 0"/>
      <geometry>
        <mesh filename="package://iCub/meshes/simmechanics/sim_sea_2-5_neck_2_prt-binary.stl" scale="0.001 0.001 0.001"/>
      </geometry>
    </collision>
  </link>
  <joint name="neck_roll" type="revolute">
    <origin xyz="0.0142999998093 0.0095 0.02079997" rpy="0 0 0"/>
    <axis xyz="0.0 0.0 1.0"/>
    <parent link="neck_1"/>
    <child link="neck_2"/>
    <limit effort="50000" lower="-0.3490658503988659" upper="0.3490658503988659" velocity="50000"/>
    <dynamics damping="0.06"/>
  </joint>
  <link name="head">
    <inertial>
      <origin xyz="-0.000574157809265 0.113511 -0.0075392" rpy="0 0 0"/>
      <mass value="1.50691"/>
      <inertia ixx="0.00680478" ixy="-1.60267e-05" ixz="7.28166e-05" iyy="0.00634736" iyz="0.000292091" izz="0.00478116"/>
    </inertial>
    <visual>
      <origin xyz="0 -0.067153 -0.0295008" rpy="0 0 0"/>
      <geometry>
        <mesh filename="package://iCub/meshes/simmechanics/sim_sea_2-5_head_prt-binary.stl" scale="0.001 0.001 0.001"/>
      </geometry>
      <material name="cyan">
        <color rgba="0 1 1 1"/>
      </material>
    </visual>
    <collision>
      <origin xyz="0 -0.067153 -0.0295008" rpy="0 0 0"/>
      <geometry>
        <mesh filename="package://iCub/meshes/simmechanics/sim_sea_2-5_head_prt-binary.stl" scale="0.001 0.001 0.001"/>
      </geometry>
    </collision>
  </link>
  <joint name="neck_yaw" type="revolute">
    <origin xyz="0 -0.022344 -0.02079997" rpy="0 0 0"/>
    <axis xyz="0.0 1.0 0.0"/>
    <parent link="neck_2"/>
    <child link="head"/>
    <limit effort="50000" lower="-0.8726646259971648" upper="0.8726646259971648" velocity="50000"/>
    <dynamics damping="0.06"/>
  </joint>
  <link name="imu_frame"/>
  <joint name="imu_frame_fixed_joint" type="fixed">
    <origin xyz="0.00950000019074 0.133444 0.0093" rpy="-1.5707963267948961 1.570796326794896 0"/>
    <parent link="head"/>
    <child link="imu_frame"/>
    <dynamics damping="0.1"/>
  </joint>
  <link name="r_shoulder_1">
    <inertial>
      <origin xyz="-0.0122656014133 3.2e-05 -0.00321064290449" rpy="0 0 0"/>
      <mass value="0.114862"/>
      <inertia ixx="2.24541e-05" ixy="-1.65173e-08" ixz="-3.55626e-06" iyy="2.29582e-05" iyz="-6.13337e-08" izz="1.00116e-05"/>
    </inertial>
    <visual>
      <origin xyz="0.0990079253076 0 -0.0265292487558" rpy="0 0 0"/>
      <geometry>
        <mesh filename="package://iCub/meshes/simmechanics/sim_sea_2-5_r_shoulder_1_prt-binary.stl" scale="0.001 0.001 0.001"/>
      </geometry>
      <material name="green"/>
    </visual>
    <collision>
      <origin xyz="0.0990079253076 0 -0.0265292487558" rpy="0 0 0"/>
      <geometry>
        <mesh filename="package://iCub/meshes/simmechanics/sim_sea_2-5_r_shoulder_1_prt-binary.stl" scale="0.001 0.001 0.001"/>
      </geometry>
    </collision>
  </link>
  <joint name="r_shoulder_pitch" type="revolute">
    <origin xyz="-0.120015999809 0.0928 0.0079693" rpy="0 -0.523598883792035 3.141592653589793"/>
    <axis xyz="-0.965925926173 0.0 0.258819275525"/>
    <parent link="chest"/>
    <child link="r_shoulder_1"/>
    <limit effort="50000" lower="-1.6667894356545847" upper="0.17453292519943295" velocity="50000"/>
    <dynamics damping="0.06"/>
  </joint>
  <link name="r_shoulder_2">
    <inertial>
      <origin xyz="-0.0214141709438 0.000271725272551 -0.0194402344535" rpy="0 0 0"/>
      <mass value="0.238162"/>
      <inertia ixx="0.000158626" ixy="-1.12091e-07" ixz="1.02574e-05" iyy="0.000206526" iyz="1.19785e-06" izz="0.000104956"/>
    </inertial>
    <visual>
      <origin xyz="0.106587808568 2.31914715418e-07 -0.0407392121175" rpy="0 0 0"/>
      <geometry>
        <mesh filename="package://iCub/meshes/simmechanics/sim_sea_2-5_r_shoulder_2_prt-binary.stl" scale="0.001 0.001 0.001"/>
      </geometry>
      <material name="white">
        <color rgba="1 1 1 1"/>
      </material>
    </visual>
    <collision>
      <origin xyz="0.106587808568 2.31914715418e-07 -0.0407392121175" rpy="0 0 0"/>
      <geometry>
        <mesh filename="package://iCub/meshes/simmechanics/sim_sea_2-5_r_shoulder_2_prt-binary.stl" scale="0.001 0.001 0.001"/>
      </geometry>
    </collision>
  </link>
  <joint name="r_shoulder_roll" type="revolute">
    <origin xyz="-0.00758046573227 0 0.0142102463639" rpy="-0.2705976115829963 -0.252680154648383 -1.5015568003498745"/>
    <axis xyz="-0.258819 -2.77555756156e-17 -0.965926"/>
    <parent link="r_shoulder_1"/>
    <child link="r_shoulder_2"/>
    <limit effort="50000" lower="0.0" upper="2.8064894372068823" velocity="50000"/>
    <dynamics damping="0.06"/>
  </joint>
  <link name="r_shoulder_3">
    <inertial>
      <origin xyz="-0.0267620766871 -6.99999999998e-06 0.0146999207713" rpy="0 0 0"/>
      <mass value="0.35913"/>
      <inertia ixx="0.000142333" ixy="3.60361e-07" ixz="4.94445e-05" iyy="0.000197746" iyz="2.65919e-07" izz="0.000151821"/>
    </inertial>
    <visual>
      <origin xyz="0.131933879164 0 -0.0353515667647" rpy="0 0 0"/>
      <geometry>
        <mesh filename="package://iCub/meshes/simmechanics/sim_sea_2-5_r_upper_arm_prt-binary.stl" scale="0.001 0.001 0.001"/>
      </geometry>
      <material name="dblue">
        <color rgba="0 0 0.8 1"/>
      </material>
    </visual>
    <collision>
      <origin xyz="0.131933879164 0 -0.0353515667647" rpy="0 0 0"/>
      <geometry>
        <mesh filename="package://iCub/meshes/simmechanics/sim_sea_2-5_r_upper_arm_prt-binary.stl" scale="0.001 0.001 0.001"/>
      </geometry>
    </collision>
  </link>
  <joint name="r_shoulder_yaw" type="revolute">
    <origin xyz="-0.0253460713232 2.32750427306e-07 -0.00538764806457" rpy="-0.2526895461750575 0.008518618321396996 0.06703988914196897"/>
    <axis xyz="0.965925843882 -2.22044604925e-16 -0.258818979447"/>
    <parent link="r_shoulder_2"/>
    <child link="r_shoulder_3"/>
    <limit effort="50000" lower="-0.6457718232379019" upper="1.3962634015954636" velocity="50000"/>
    <dynamics damping="0.06"/>
  </joint>
  <link name="r_upper_arm">
    <inertial>
      <origin xyz="-0.006087 0.000126 0.0293121" rpy="0 1.30899700696774 0"/>
      <mass value="0.745104"/>
      <inertia ixx="0.000509527" ixy="1.19292e-06" ixz="-1.17426e-05" iyy="0.000668487" iyz="1.13363e-06" izz="0.000599254"/>
    </inertial>
    <visual>
      <origin xyz="-0.015 0 -0.1933" rpy="0 1.30899700696774 0"/>
      <geometry>
        <mesh filename="package://iCub/meshes/simmechanics/sim_sea_2-5_r_elbow_prt-binary.stl" scale="0.001 0.001 0.001"/>
      </geometry>
      <material name="dgreen">
        <color rgba="0.1 0.8 0.1 1"/>
      </material>
    </visual>
    <collision>
      <origin xyz="-0.015 0 -0.1933" rpy="0 1.30899700696774 0"/>
      <geometry>
        <mesh filename="package://iCub/meshes/simmechanics/sim_sea_2-5_r_elbow_prt-binary.stl" scale="0.001 0.001 0.001"/>
      </geometry>
    </collision>
  </link>
  <joint name="r_arm_ft_sensor" type="fixed">
    <origin xyz="-0.0508973017665 0 0.0291670296206" rpy="0 -1.3089970069677397 0"/>
    <parent link="r_shoulder_3"/>
    <child link="r_upper_arm"/>
    <dynamics damping="0.1"/>
  </joint>
  <link name="r_upper_arm_mtb_acc_2b10"/>
  <joint name="r_upper_arm_mtb_acc_2b10_fixed_joint" type="fixed">
    <origin xyz="-0.0412194 0.029588 0.0295279" rpy="1.5707954636549208 1.5707838122500957 -2.6825716116363636"/>
    <parent link="r_upper_arm"/>
    <child link="r_upper_arm_mtb_acc_2b10"/>
    <dynamics damping="0.1"/>
  </joint>
  <link name="r_upper_arm_mtb_acc_2b11"/>
  <joint name="r_upper_arm_mtb_acc_2b11_fixed_joint" type="fixed">
    <origin xyz="-0.0430568 0.02868 0.0760604" rpy="-1.570796146955223 -1.570503507405979 0.4590217252188694"/>
    <parent link="r_upper_arm"/>
    <child link="r_upper_arm_mtb_acc_2b11"/>
    <dynamics damping="0.1"/>
  </joint>
  <link name="r_upper_arm_mtb_acc_2b12"/>
  <joint name="r_upper_arm_mtb_acc_2b12_fixed_joint" type="fixed">
    <origin xyz="-0.0430554 0.028681 0.0049922" rpy="-1.111774421683548 -1.5707963267948963 0"/>
    <parent link="r_upper_arm"/>
    <child link="r_upper_arm_mtb_acc_2b12"/>
    <dynamics damping="0.1"/>
  </joint>
  <link name="r_upper_arm_mtb_acc_2b13"/>
  <joint name="r_upper_arm_mtb_acc_2b13_fixed_joint" type="fixed">
    <origin xyz="0.010593237 0.02835 -0.010738" rpy="1.5707963270155092 -0.00021452036204143253 2.4780367445076594"/>
    <parent link="r_upper_arm"/>
    <child link="r_upper_arm_mtb_acc_2b13"/>
    <dynamics damping="0.1"/>
  </joint>
  <link name="r_elbow_1">
    <inertial>
      <origin xyz="-0.00673912932843 0.0188019 -0.00465769236154" rpy="0 0 0"/>
      <mass value="0.267903"/>
      <inertia ixx="8.13344e-05" ixy="7.36974e-06" ixz="-1.04536e-05" iyy="5.86947e-05" iyz="3.92498e-06" izz="9.68353e-05"/>
    </inertial>
    <visual>
      <origin xyz="0.259390463317 0.0224999 -0.0850325886962" rpy="0 0 0"/>
      <geometry>
        <mesh filename="package://iCub/meshes/simmechanics/sim_sea_2-5_r_elbow_prosup_prt-binary.stl" scale="0.001 0.001 0.001"/>
      </geometry>
      <material name="gray">
        <color rgba="0.5 0.5 0.5 1"/>
      </material>
    </visual>
    <collision>
      <origin xyz="0.259390463317 0.0224999 -0.0850325886962" rpy="0 0 0"/>
      <geometry>
        <mesh filename="package://iCub/meshes/simmechanics/sim_sea_2-5_r_elbow_prosup_prt-binary.stl" scale="0.001 0.001 0.001"/>
      </geometry>
    </collision>
  </link>
  <joint name="r_elbow" type="revolute">
    <origin xyz="0 -0.0224999 0.07926" rpy="0 1.3089970069677397 0"/>
    <axis xyz="2.22044604925e-16 1.0 0.0"/>
    <parent link="r_upper_arm"/>
    <child link="r_elbow_1"/>
    <limit effort="50000" lower="0.2617993877991494" upper="1.8500490071139892" velocity="50000"/>
    <dynamics damping="0.06"/>
  </joint>
  <link name="r_forearm">
    <inertial>
      <origin xyz="-0.0404391133886 -0.000328 0.00532733448387" rpy="0 0 0"/>
      <mass value="0.6347"/>
      <inertia ixx="0.000370044" ixy="-1.65419e-06" ixz="0.00010538" iyy="0.000672279" iyz="1.1456e-06" izz="0.000553637"/>
    </inertial>
    <visual>
      <origin xyz="0.296886967375 0 -0.0795506015227" rpy="0 0 0"/>
      <geometry>
        <mesh filename="package://iCub/meshes/simmechanics/sim_sea_2-5_r_forearm_prt-binary.stl" scale="0.001 0.001 0.001"/>
      </geometry>
      <material name="green"/>
    </visual>
    <collision>
      <origin xyz="0.296886967375 0 -0.0795506015227" rpy="0 0 0"/>
      <geometry>
        <mesh filename="package://iCub/meshes/simmechanics/sim_sea_2-5_r_forearm_prt-binary.stl" scale="0.001 0.001 0.001"/>
      </geometry>
    </collision>
  </link>
  <joint name="r_wrist_prosup" type="revolute">
    <origin xyz="-0.0384624299027 0.0224999 -0.00522316819403" rpy="0 0 0"/>
    <axis xyz="0.965925843882 -2.22044604925e-16 -0.258818979447"/>
    <parent link="r_elbow_1"/>
    <child link="r_forearm"/>
    <limit effort="50000" lower="-1.0471975511965976" upper="1.0471975511965976" velocity="50000"/>
    <dynamics damping="0.06"/>
  </joint>
  <link name="r_forearm_mtb_acc_2b7"/>
  <joint name="r_forearm_mtb_acc_2b7_fixed_joint" type="fixed">
    <origin xyz="-0.0768727847342 0.005497 -0.0110479126068" rpy="0.2617994999795781 0.0003704130423278739 1.5712581686273495"/>
    <parent link="r_forearm"/>
    <child link="r_forearm_mtb_acc_2b7"/>
    <dynamics damping="0.1"/>
  </joint>
  <link name="r_forearm_mtb_acc_2b8"/>
  <joint name="r_forearm_mtb_acc_2b8_fixed_joint" type="fixed">
    <origin xyz="-0.0514186150796 0.015786 0.0407521537277" rpy="-0.6611439460918273 0.147825248461156 0.09207011470296811"/>
    <parent link="r_forearm"/>
    <child link="r_forearm_mtb_acc_2b8"/>
    <dynamics damping="0.1"/>
  </joint>
  <link name="r_forearm_mtb_acc_2b9"/>
  <joint name="r_forearm_mtb_acc_2b9_fixed_joint" type="fixed">
    <origin xyz="-0.0216379956759 0.027924 -0.0132490254018" rpy="-1.766826267315445 0.2611912256456085 0.05404834437200347"/>
    <parent link="r_forearm"/>
    <child link="r_forearm_mtb_acc_2b9"/>
    <dynamics damping="0.1"/>
  </joint>
  <link name="r_forearm_skin_0"/>
  <joint name="r_forearm_skin_0_fixed_joint" type="fixed">
    <origin xyz="-0.0454493286618 0.030077 -0.00628656037901" rpy="1.6918152229167889 -0.27102674434071783 -3.0688043822713253"/>
    <parent link="r_forearm"/>
    <child link="r_forearm_skin_0"/>
    <dynamics damping="0.1"/>
  </joint>
  <link name="r_forearm_skin_1"/>
  <joint name="r_forearm_skin_1_fixed_joint" type="fixed">
    <origin xyz="-0.0333728935826 0.028826 -0.0198456867711" rpy="1.8669402327820506 -0.27444253376399086 -3.0994697798425186"/>
    <parent link="r_forearm"/>
    <child link="r_forearm_skin_1"/>
    <dynamics damping="0.1"/>
  </joint>
  <link name="r_forearm_skin_2"/>
  <joint name="r_forearm_skin_2_fixed_joint" type="fixed">
    <origin xyz="-0.0146988929852 0.031279 -0.0160117338371" rpy="1.7284728701922574 -0.26401521911581066 -3.127332606870116"/>
    <parent link="r_forearm"/>
    <child link="r_forearm_skin_2"/>
    <dynamics damping="0.1"/>
  </joint>
  <link name="r_forearm_skin_3"/>
  <joint name="r_forearm_skin_3_fixed_joint" type="fixed">
    <origin xyz="-0.045567293622 -0.030891 -0.00633000929351" rpy="-1.694872808587699 -0.2697577271044894 3.0795974357388127"/>
    <parent link="r_forearm"/>
    <child link="r_forearm_skin_3"/>
    <dynamics damping="0.1"/>
  </joint>
  <link name="r_forearm_skin_4"/>
  <joint name="r_forearm_skin_4_fixed_joint" type="fixed">
    <origin xyz="-0.0635326332996 -0.0281163 -0.00899784258066" rpy="-1.807349601935264 -0.03931317963272516 2.9799764363205914"/>
    <parent link="r_forearm"/>
    <child link="r_forearm_skin_4"/>
    <dynamics damping="0.1"/>
  </joint>
  <link name="r_forearm_skin_5"/>
  <joint name="r_forearm_skin_5_fixed_joint" type="fixed">
    <origin xyz="-0.0688211941968 -0.0179483 -0.0231133361791" rpy="-2.541047580603648 -0.38562726064167885 3.0548698966694605"/>
    <parent link="r_forearm"/>
    <child link="r_forearm_skin_5"/>
    <dynamics damping="0.1"/>
  </joint>
  <link name="r_forearm_skin_6"/>
  <joint name="r_forearm_skin_6_fixed_joint" type="fixed">
    <origin xyz="-0.0333948436255 -0.0295479 -0.0198325583433" rpy="-1.8662816465326075 -0.27288633618099856 3.104485850211511"/>
    <parent link="r_forearm"/>
    <child link="r_forearm_skin_6"/>
    <dynamics damping="0.1"/>
  </joint>
  <link name="r_forearm_skin_7"/>
  <joint name="r_forearm_skin_7_fixed_joint" type="fixed">
    <origin xyz="-0.0147224260074 -0.0319422 -0.0159326482703" rpy="-1.725646408570656 -0.26399290072226816 3.127212542664466"/>
    <parent link="r_forearm"/>
    <child link="r_forearm_skin_7"/>
    <dynamics damping="0.1"/>
  </joint>
  <link name="r_forearm_skin_8"/>
  <joint name="r_forearm_skin_8_fixed_joint" type="fixed">
    <origin xyz="-0.0228528628554 -0.0097862 -0.041885146375" rpy="-2.9480197913728667 -0.27060509051232057 3.139805572846308"/>
    <parent link="r_forearm"/>
    <child link="r_forearm_skin_8"/>
    <dynamics damping="0.1"/>
  </joint>
  <link name="r_forearm_skin_9"/>
  <joint name="r_forearm_skin_9_fixed_joint" type="fixed">
    <origin xyz="-0.0376032734683 -0.018955 -0.0340163371186" rpy="-2.5840651770760545 -0.29332171959950487 3.121284073962177"/>
    <parent link="r_forearm"/>
    <child link="r_forearm_skin_9"/>
    <dynamics damping="0.1"/>
  </joint>
  <link name="r_forearm_skin_10"/>
  <joint name="r_forearm_skin_10_fixed_joint" type="fixed">
    <origin xyz="-0.0542285210888 -0.0097861 -0.0321469082866" rpy="-2.94123313405522 -0.32830447192219026 3.12762637539622"/>
    <parent link="r_forearm"/>
    <child link="r_forearm_skin_10"/>
    <dynamics damping="0.1"/>
  </joint>
  <link name="r_forearm_skin_11"/>
  <joint name="r_forearm_skin_11_fixed_joint" type="fixed">
    <origin xyz="-0.0542240912024 0.009043 -0.0321431259452" rpy="2.9392983595663433 -0.3291013897448521 -3.127319164460641"/>
    <parent link="r_forearm"/>
    <child link="r_forearm_skin_11"/>
    <dynamics damping="0.1"/>
  </joint>
  <link name="r_forearm_skin_12"/>
  <joint name="r_forearm_skin_12_fixed_joint" type="fixed">
    <origin xyz="-0.0375994633868 0.018216 -0.0340191179961" rpy="2.5830350596406384 -0.2948305020697442 -3.120265803141759"/>
    <parent link="r_forearm"/>
    <child link="r_forearm_skin_12"/>
    <dynamics damping="0.1"/>
  </joint>
  <link name="r_forearm_skin_13"/>
  <joint name="r_forearm_skin_13_fixed_joint" type="fixed">
    <origin xyz="-0.0228550868405 0.009048 -0.0418919009209" rpy="2.948966791979468 -0.27058394718877915 -3.1398188035221444"/>
    <parent link="r_forearm"/>
    <child link="r_forearm_skin_13"/>
    <dynamics damping="0.1"/>
  </joint>
  <link name="r_forearm_skin_14"/>
  <joint name="r_forearm_skin_14_fixed_joint" type="fixed">
    <origin xyz="-0.0687703276364 0.01716 -0.0230239558511" rpy="2.480449918677725 -0.29554256628052245 -2.918773491387445"/>
    <parent link="r_forearm"/>
    <child link="r_forearm_skin_14"/>
    <dynamics damping="0.1"/>
  </joint>
  <link name="r_forearm_skin_15"/>
  <joint name="r_forearm_skin_15_fixed_joint" type="fixed">
    <origin xyz="-0.0633786419662 0.027145 -0.00879405455544" rpy="1.8049276974140638 -0.289783281915754 -3.027658914283702"/>
    <parent link="r_forearm"/>
    <child link="r_forearm_skin_15"/>
    <dynamics damping="0.1"/>
  </joint>
  <link name="r_forearm_skin_16"/>
  <joint name="r_forearm_skin_16_fixed_joint" type="fixed">
    <origin xyz="-0.03792482187 0.030487 0.0206369503605" rpy="1.4128000702560044 -0.25082462138972744 -3.0657274234313623"/>
    <parent link="r_forearm"/>
    <child link="r_forearm_skin_16"/>
    <dynamics damping="0.1"/>
  </joint>
  <link name="r_forearm_skin_17"/>
  <joint name="r_forearm_skin_17_fixed_joint" type="fixed">
    <origin xyz="-0.0543170548821 0.027725 0.0303291240179" rpy="1.2722371620529929 -0.23059304703026895 -3.031955428370696"/>
    <parent link="r_forearm"/>
    <child link="r_forearm_skin_17"/>
    <dynamics damping="0.1"/>
  </joint>
  <link name="r_forearm_skin_19"/>
  <joint name="r_forearm_skin_19_fixed_joint" type="fixed">
    <origin xyz="-0.0381266107138 -0.0312941 0.020690605393" rpy="-1.415608887032208 -0.2525692902263516 3.0771521788870553"/>
    <parent link="r_forearm"/>
    <child link="r_forearm_skin_19"/>
    <dynamics damping="0.1"/>
  </joint>
  <link name="r_forearm_skin_22"/>
  <joint name="r_forearm_skin_22_fixed_joint" type="fixed">
    <origin xyz="-0.0544173950421 -0.0287223 0.0306037516609" rpy="-1.2658242727950597 -0.2343281513787831 3.0478831797095465"/>
    <parent link="r_forearm"/>
    <child link="r_forearm_skin_22"/>
    <dynamics damping="0.1"/>
  </joint>
  <link name="r_forearm_skin_24"/>
  <joint name="r_forearm_skin_24_fixed_joint" type="fixed">
    <origin xyz="-0.0700345319564 -0.0097164 0.050069108714" rpy="-0.23489327644017136 -0.03881729939817662 3.0867634545899256"/>
    <parent link="r_forearm"/>
    <child link="r_forearm_skin_24"/>
    <dynamics damping="0.1"/>
  </joint>
  <link name="r_forearm_skin_25"/>
  <joint name="r_forearm_skin_25_fixed_joint" type="fixed">
    <origin xyz="-0.0535999216295 -0.0182238 0.0454698125045" rpy="-0.5642955277146758 -0.13698027219744066 3.05963182792421"/>
    <parent link="r_forearm"/>
    <child link="r_forearm_skin_25"/>
    <dynamics damping="0.1"/>
  </joint>
  <link name="r_forearm_skin_28"/>
  <joint name="r_forearm_skin_28_fixed_joint" type="fixed">
    <origin xyz="-0.0535859272148 0.017412 0.045352037397" rpy="0.5907706440800042 -0.05316072260629336 3.1059708116712708"/>
    <parent link="r_forearm"/>
    <child link="r_forearm_skin_28"/>
    <dynamics damping="0.1"/>
  </joint>
  <link name="r_forearm_skin_29"/>
  <joint name="r_forearm_skin_29_fixed_joint" type="fixed">
    <origin xyz="-0.0700355805031 0.008954 0.0500111036233" rpy="0.24863098220864202 -0.03831365567858803 -3.0832899911631824"/>
    <parent link="r_forearm"/>
    <child link="r_forearm_skin_29"/>
    <dynamics damping="0.1"/>
  </joint>
  <link name="r_forearm_dh_frame"/>
  <joint name="r_forearm_dh_frame_fixed_joint" type="fixed">
    <origin xyz="-0.102871102373 7.00000000002e-06 0.0275642213111" rpy="-0.26179931982715643 0 -1.5707963267948968"/>
    <parent link="r_forearm"/>
    <child link="r_forearm_dh_frame"/>
    <dynamics damping="0.1"/>
  </joint>
  <link name="r_wrist_1">
    <inertial>
      <origin xyz="0.000986101955547 -0.001176 0.00410132736724" rpy="0 0 0"/>
      <mass value="0.0362615"/>
      <inertia ixx="5.57722e-06" ixy="-3.10462e-08" ixz="-9.44554e-07" iyy="5.29845e-06" iyz="-1.59685e-07" izz="1.87724e-06"/>
    </inertial>
    <visual>
      <origin xyz="0.400392176248 -7.00000000009e-06 -0.104748304516" rpy="0 0 0"/>
      <geometry>
        <mesh filename="package://iCub/meshes/simmechanics/sim_sea_2-5_r_wrist_pitch_prt-binary.stl" scale="0.001 0.001 0.001"/>
      </geometry>
      <material name="black"/>
    </visual>
    <collision>
      <origin xyz="0.400392176248 -7.00000000009e-06 -0.104748304516" rpy="0 0 0"/>
      <geometry>
        <mesh filename="package://iCub/meshes/simmechanics/sim_sea_2-5_r_wrist_pitch_prt-binary.stl" scale="0.001 0.001 0.001"/>
      </geometry>
    </collision>
  </link>
  <joint name="r_wrist_pitch" type="revolute">
    <origin xyz="-0.103505208873 7.00000000002e-06 0.0251977029936" rpy="0 0 0"/>
    <axis xyz="0.258818979447 0.0 0.965925843882"/>
    <parent link="r_forearm"/>
    <child link="r_wrist_1"/>
    <limit effort="50000" lower="-1.3962634015954636" upper="0.4363323129985824" velocity="50000"/>
    <dynamics damping="0.06"/>
  </joint>
  <link name="r_hand">
    <inertial>
      <origin xyz="-0.064668163717 0.0056002 0.0226812940918" rpy="0 0 0"/>
      <mass value="0.248289"/>
      <inertia ixx="0.000162381" ixy="-2.3536e-06" ixz="3.61526e-05" iyy="0.00043138" iyz="2.07146e-05" izz="0.00030575"/>
    </inertial>
    <visual>
      <origin xyz="0.399758069749 0.0194929 -0.107114822834" rpy="0 0 0"/>
      <geometry>
        <mesh filename="package://iCub/meshes/simmechanics/sim_sea_2-5_r_hand_prt-binary.stl" scale="0.001 0.001 0.001"/>
      </geometry>
      <material name="red"/>
    </visual>
    <collision>
      <origin xyz="0.399758069749 0.0194929 -0.107114822834" rpy="0 0 0"/>
      <geometry>
        <mesh filename="package://iCub/meshes/simmechanics/sim_sea_2-5_r_hand_prt-binary.stl" scale="0.001 0.001 0.001"/>
      </geometry>
    </collision>
  </link>
  <joint name="r_wrist_yaw" type="revolute">
    <origin xyz="0.000634106499644 -0.0194999 0.00236651831751" rpy="0 0 0"/>
    <axis xyz="2.22044604925e-16 1.0 0.0"/>
    <parent link="r_wrist_1"/>
    <child link="r_hand"/>
    <limit effort="50000" lower="-0.3490658503988659" upper="0.4363323129985824" velocity="50000"/>
    <dynamics damping="0.06"/>
  </joint>
  <link name="r_hand_dh_frame"/>
  <joint name="r_hand_dh_frame_fixed_joint" type="fixed">
    <origin xyz="-0.0576542978428 -0.0055568 0.0136938323083" rpy="-1.5707963267948963 -0.2617993198271562 3.141592653589793"/>
    <parent link="r_hand"/>
    <child link="r_hand_dh_frame"/>
    <dynamics damping="0.1"/>
  </joint>
  <link name="l_shoulder_1">
    <inertial>
      <origin xyz="-0.008985 -3.3e-05 -0.0088998" rpy="0 0 0"/>
      <mass value="0.114882"/>
      <inertia ixx="2.24676e-05" ixy="-1.77064e-08" ixz="3.55951e-06" iyy="2.29712e-05" iyz="6.57597e-08" izz="1.00139e-05"/>
    </inertial>
    <visual>
      <origin xyz="-0.120257482 0 -0.032223" rpy="0 0 0"/>
      <geometry>
        <mesh filename="package://iCub/meshes/simmechanics/sim_sea_2-5_l_shoulder_1_prt-binary.stl" scale="0.001 0.001 0.001"/>
      </geometry>
      <material name="blue"/>
    </visual>
    <collision>
      <origin xyz="-0.120257482 0 -0.032223" rpy="0 0 0"/>
      <geometry>
        <mesh filename="package://iCub/meshes/simmechanics/sim_sea_2-5_l_shoulder_1_prt-binary.stl" scale="0.001 0.001 0.001"/>
      </geometry>
    </collision>
  </link>
  <joint name="l_shoulder_pitch" type="revolute">
    <origin xyz="0.120016000191 0.0928 0.0079693" rpy="0 0 0"/>
    <axis xyz="0.965926 0.0 0.258819"/>
    <parent link="chest"/>
    <child link="l_shoulder_1"/>
    <limit effort="50000" lower="-1.6667894356545847" upper="0.17453292519943295" velocity="50000"/>
    <dynamics damping="0.06"/>
  </joint>
  <link name="l_shoulder_2">
    <inertial>
      <origin xyz="0.0214745951272 0.000268957899687 -0.0194107361535" rpy="0 0 0"/>
      <mass value="0.238162"/>
      <inertia ixx="0.000159621" ixy="1.19701e-07" ixz="-1.29687e-05" iyy="0.000222574" iyz="1.20112e-06" izz="0.000120056"/>
    </inertial>
    <visual>
      <origin xyz="-0.106586691581 1.10800934344e-07 -0.040743380771" rpy="0 0 0"/>
      <geometry>
        <mesh filename="package://iCub/meshes/simmechanics/sim_sea_2-5_l_shoulder_2_prt-binary.stl" scale="0.001 0.001 0.001"/>
      </geometry>
      <material name="yellow"/>
    </visual>
    <collision>
      <origin xyz="-0.106586691581 1.10800934344e-07 -0.040743380771" rpy="0 0 0"/>
      <geometry>
        <mesh filename="package://iCub/meshes/simmechanics/sim_sea_2-5_l_shoulder_2_prt-binary.stl" scale="0.001 0.001 0.001"/>
      </geometry>
    </collision>
  </link>
  <joint name="l_shoulder_roll" type="revolute">
    <origin xyz="-0.013671 0 0.0085204" rpy="0.2705973179159596 0.25268017754236044 -1.5015568855866173"/>
    <axis xyz="-0.258819 2.77555756156e-17 0.965926"/>
    <parent link="l_shoulder_1"/>
    <child link="l_shoulder_2"/>
    <limit effort="50000" lower="0.0" upper="2.8064894372068823" velocity="50000"/>
    <dynamics damping="0.06"/>
  </joint>
  <link name="l_shoulder_3">
    <inertial>
      <origin xyz="0.026798412222 -1.6e-05 0.0146956806177" rpy="0 0 0"/>
      <mass value="0.35913"/>
      <inertia ixx="0.00014245" ixy="-2.22441e-07" ixz="-4.95846e-05" iyy="0.000197807" iyz="1.07538e-07" izz="0.000151706"/>
    </inertial>
    <visual>
      <origin xyz="-0.131901037685 0 -0.0353427669194" rpy="0 0 0"/>
      <geometry>
        <mesh filename="package://iCub/meshes/simmechanics/sim_sea_2-5_l_upper_arm_prt-binary.stl" scale="0.001 0.001 0.001"/>
      </geometry>
      <material name="pink"/>
    </visual>
    <collision>
      <origin xyz="-0.131901037685 0 -0.0353427669194" rpy="0 0 0"/>
      <geometry>
        <mesh filename="package://iCub/meshes/simmechanics/sim_sea_2-5_l_upper_arm_prt-binary.stl" scale="0.001 0.001 0.001"/>
      </geometry>
    </collision>
  </link>
  <joint name="l_shoulder_yaw" type="revolute">
    <origin xyz="0.0253143468312 1.11636438205e-07 -0.00540061656265" rpy="-0.2526895461750575 -0.008518618321396996 -0.06703988914196897"/>
    <axis xyz="0.965925843882 2.22044604925e-16 0.258818979447"/>
    <parent link="l_shoulder_2"/>
    <child link="l_shoulder_3"/>
    <limit effort="50000" lower="-0.6457718232379019" upper="1.3962634015954636" velocity="50000"/>
    <dynamics damping="0.06"/>
  </joint>
  <link name="l_upper_arm">
    <inertial>
      <origin xyz="-0.006121 -0.000189 0.0293684" rpy="0 -1.30899700696774 -3.1415926535897922"/>
      <mass value="0.746799"/>
      <inertia ixx="0.000509731" ixy="-6.90767e-07" ixz="1.20048e-05" iyy="0.00067086" iyz="3.11833e-06" izz="0.000601202"/>
    </inertial>
    <visual>
      <origin xyz="-0.015 0 -0.1933" rpy="0 -1.30899700696774 -3.1415926535897922"/>
      <geometry>
        <mesh filename="package://iCub/meshes/simmechanics/sim_sea_2-5_l_elbow_prt-binary.stl" scale="0.001 0.001 0.001"/>
      </geometry>
      <material name="cyan"/>
    </visual>
    <collision>
      <origin xyz="-0.015 0 -0.1933" rpy="0 -1.30899700696774 -3.1415926535897922"/>
      <geometry>
        <mesh filename="package://iCub/meshes/simmechanics/sim_sea_2-5_l_elbow_prt-binary.stl" scale="0.001 0.001 0.001"/>
      </geometry>
    </collision>
  </link>
  <joint name="l_arm_ft_sensor" type="fixed">
    <origin xyz="0.0509301432452 0 0.0291758294659" rpy="0 -1.3089970069677395 3.1415926535897927"/>
    <parent link="l_shoulder_3"/>
    <child link="l_upper_arm"/>
    <dynamics damping="0.1"/>
  </joint>
  <link name="l_upper_arm_mtb_acc_1b10"/>
  <joint name="l_upper_arm_mtb_acc_1b10_fixed_joint" type="fixed">
    <origin xyz="-0.0430554 -0.028681 0.0295279" rpy="-1.5707965066353287 -1.5705035074059788 2.682570928371598"/>
    <parent link="l_upper_arm"/>
    <child link="l_upper_arm_mtb_acc_1b10"/>
    <dynamics damping="0.1"/>
  </joint>
  <link name="l_upper_arm_mtb_acc_1b11"/>
  <joint name="l_upper_arm_mtb_acc_1b11_fixed_joint" type="fixed">
    <origin xyz="-0.0412181 -0.029589 0.0760604" rpy="-1.5707965066353287 -1.5705035074059788 2.682570928371598"/>
    <parent link="l_upper_arm"/>
    <child link="l_upper_arm_mtb_acc_1b11"/>
    <dynamics damping="0.1"/>
  </joint>
  <link name="l_upper_arm_mtb_acc_1b12"/>
  <joint name="l_upper_arm_mtb_acc_1b12_fixed_joint" type="fixed">
    <origin xyz="-0.0412194 -0.029588 0.0049921" rpy="-1.570797189926001 -1.5707838122500957 2.6825716116165723"/>
    <parent link="l_upper_arm"/>
    <child link="l_upper_arm_mtb_acc_1b12"/>
    <dynamics damping="0.1"/>
  </joint>
  <link name="l_upper_arm_mtb_acc_1b13"/>
  <joint name="l_upper_arm_mtb_acc_1b13_fixed_joint" type="fixed">
    <origin xyz="0.010592709 -0.028351 -0.0086914" rpy="-1.570796326574284 0.00021452036204176565 -2.478036744507659"/>
    <parent link="l_upper_arm"/>
    <child link="l_upper_arm_mtb_acc_1b13"/>
    <dynamics damping="0.1"/>
  </joint>
  <link name="l_elbow_1">
    <inertial>
      <origin xyz="0.00673912932843 0.0303019 -0.00465769236154" rpy="0 0 0"/>
      <mass value="0.267903"/>
      <inertia ixx="8.13352e-05" ixy="-7.37159e-06" ixz="1.04505e-05" iyy="5.86823e-05" iyz="3.9319e-06" izz="9.68469e-05"/>
    </inertial>
    <visual>
      <origin xyz="-0.259390463317 0.0339999 -0.0850325886962" rpy="0 0 0"/>
      <geometry>
        <mesh filename="package://iCub/meshes/simmechanics/sim_sea_2-5_l_elbow_prosup_prt-binary.stl" scale="0.001 0.001 0.001"/>
      </geometry>
      <material name="green"/>
    </visual>
    <collision>
      <origin xyz="-0.259390463317 0.0339999 -0.0850325886962" rpy="0 0 0"/>
      <geometry>
        <mesh filename="package://iCub/meshes/simmechanics/sim_sea_2-5_l_elbow_prosup_prt-binary.stl" scale="0.001 0.001 0.001"/>
      </geometry>
    </collision>
  </link>
  <joint name="l_elbow" type="revolute">
    <origin xyz="0 0.0339999 0.07926" rpy="0 -1.3089970069677395 -3.141592653589793"/>
    <axis xyz="2.22044604925e-16 -1.0 0.0"/>
    <parent link="l_upper_arm"/>
    <child link="l_elbow_1"/>
    <limit effort="50000" lower="0.2617993877991494" upper="1.8500490071139892" velocity="50000"/>
    <dynamics damping="0.06"/>
  </joint>
  <link name="l_forearm">
    <inertial>
      <origin xyz="0.0404511828823 -0.000686 0.00532363214379" rpy="0 0 0"/>
      <mass value="0.636185"/>
      <inertia ixx="0.000371447" ixy="4.34562e-06" ixz="-0.000105871" iyy="0.000674229" iyz="4.05222e-06" izz="0.000557115"/>
    </inertial>
    <visual>
      <origin xyz="-0.296886967375 0 -0.0795506015227" rpy="0 0 0"/>
      <geometry>
        <mesh filename="package://iCub/meshes/simmechanics/sim_sea_2-5_l_forearm_prt-binary.stl" scale="0.001 0.001 0.001"/>
      </geometry>
      <material name="white"/>
    </visual>
    <collision>
      <origin xyz="-0.296886967375 0 -0.0795506015227" rpy="0 0 0"/>
      <geometry>
        <mesh filename="package://iCub/meshes/simmechanics/sim_sea_2-5_l_forearm_prt-binary.stl" scale="0.001 0.001 0.001"/>
      </geometry>
    </collision>
  </link>
  <joint name="l_wrist_prosup" type="revolute">
    <origin xyz="0.0384624299027 0.0339999 -0.00522316819403" rpy="0 0 0"/>
    <axis xyz="0.965925843882 2.22044604925e-16 0.258818979447"/>
    <parent link="l_elbow_1"/>
    <child link="l_forearm"/>
    <limit effort="50000" lower="-1.0471975511965976" upper="1.0471975511965976" velocity="50000"/>
    <dynamics damping="0.06"/>
  </joint>
  <link name="l_forearm_mtb_acc_1b7"/>
  <joint name="l_forearm_mtb_acc_1b7_fixed_joint" type="fixed">
    <origin xyz="0.0768727847342 -0.005483 -0.0110479126068" rpy="0.261799499979528 0.00037041304232823477 -1.5703344849624448"/>
    <parent link="l_forearm"/>
    <child link="l_forearm_mtb_acc_1b7"/>
    <dynamics damping="0.1"/>
  </joint>
  <link name="l_forearm_mtb_acc_1b8"/>
  <joint name="l_forearm_mtb_acc_1b8_fixed_joint" type="fixed">
    <origin xyz="0.0514241740607 -0.0180279 0.0407507258436" rpy="-0.6611439460918273 0.14782524846115594 -3.0495225388868246"/>
    <parent link="l_forearm"/>
    <child link="l_forearm_mtb_acc_1b8"/>
    <dynamics damping="0.1"/>
  </joint>
  <link name="l_forearm_mtb_acc_1b9"/>
  <joint name="l_forearm_mtb_acc_1b9_fixed_joint" type="fixed">
    <origin xyz="0.0220991874996 0.025657 -0.0151174243212" rpy="1.766821342184715 0.2610998298471551 3.0875254820176163"/>
    <parent link="l_forearm"/>
    <child link="l_forearm_mtb_acc_1b9"/>
    <dynamics damping="0.1"/>
  </joint>
  <link name="l_forearm_skin_0"/>
  <joint name="l_forearm_skin_0_fixed_joint" type="fixed">
    <origin xyz="0.0454493286618 -0.0323169 -0.00628656037901" rpy="1.6918152229167884 -0.2710267443407179 0.07278827131846853"/>
    <parent link="l_forearm"/>
    <child link="l_forearm_skin_0"/>
    <dynamics damping="0.1"/>
  </joint>
  <link name="l_forearm_skin_1"/>
  <joint name="l_forearm_skin_1_fixed_joint" type="fixed">
    <origin xyz="0.0333728935826 -0.0310662 -0.0198456867711" rpy="1.8669402327820506 -0.27444253376399064 0.04212287374727489"/>
    <parent link="l_forearm"/>
    <child link="l_forearm_skin_1"/>
    <dynamics damping="0.1"/>
  </joint>
  <link name="l_forearm_skin_2"/>
  <joint name="l_forearm_skin_2_fixed_joint" type="fixed">
    <origin xyz="0.0146988929852 -0.0335184 -0.0160117338371" rpy="1.7284728701922578 -0.2640152191158104 0.014260046719677696"/>
    <parent link="l_forearm"/>
    <child link="l_forearm_skin_2"/>
    <dynamics damping="0.1"/>
  </joint>
  <link name="l_forearm_skin_3"/>
  <joint name="l_forearm_skin_3_fixed_joint" type="fixed">
    <origin xyz="0.045567293622 0.028651 -0.00633000929351" rpy="-1.6948728085876998 -0.26975772710448964 -0.06199521785098036"/>
    <parent link="l_forearm"/>
    <child link="l_forearm_skin_3"/>
    <dynamics damping="0.1"/>
  </joint>
  <link name="l_forearm_skin_4"/>
  <joint name="l_forearm_skin_4_fixed_joint" type="fixed">
    <origin xyz="0.0635326332996 0.025877 -0.00899784258066" rpy="-1.8174787010829498 -0.28740688488516286 -0.09983161528264395"/>
    <parent link="l_forearm"/>
    <child link="l_forearm_skin_4"/>
    <dynamics damping="0.1"/>
  </joint>
  <link name="l_forearm_skin_5"/>
  <joint name="l_forearm_skin_5_fixed_joint" type="fixed">
    <origin xyz="0.0688211941968 0.015709 -0.0231133361791" rpy="-2.541047580603648 -0.38562726064167896 -0.08672275692033206"/>
    <parent link="l_forearm"/>
    <child link="l_forearm_skin_5"/>
    <dynamics damping="0.1"/>
  </joint>
  <link name="l_forearm_skin_6"/>
  <joint name="l_forearm_skin_6_fixed_joint" type="fixed">
    <origin xyz="0.0333948436255 0.027308 -0.0198325583433" rpy="-1.866281646532607 -0.27288633618099845 -0.037106803378281775"/>
    <parent link="l_forearm"/>
    <child link="l_forearm_skin_6"/>
    <dynamics damping="0.1"/>
  </joint>
  <link name="l_forearm_skin_7"/>
  <joint name="l_forearm_skin_7_fixed_joint" type="fixed">
    <origin xyz="0.0147224260074 0.029702 -0.0159326482703" rpy="-1.7256464085706567 -0.2639929007222682 -0.014380110925327112"/>
    <parent link="l_forearm"/>
    <child link="l_forearm_skin_7"/>
    <dynamics damping="0.1"/>
  </joint>
  <link name="l_forearm_skin_8"/>
  <joint name="l_forearm_skin_8_fixed_joint" type="fixed">
    <origin xyz="0.0228528628554 0.007546 -0.041885146375" rpy="-2.9480197913728667 -0.27060509051232073 -0.0017870807434848114"/>
    <parent link="l_forearm"/>
    <child link="l_forearm_skin_8"/>
    <dynamics damping="0.1"/>
  </joint>
  <link name="l_forearm_skin_9"/>
  <joint name="l_forearm_skin_9_fixed_joint" type="fixed">
    <origin xyz="0.0376032734683 0.016715 -0.0340163371186" rpy="-2.5840651770760545 -0.29332171959950476 -0.020308579627615755"/>
    <parent link="l_forearm"/>
    <child link="l_forearm_skin_9"/>
    <dynamics damping="0.1"/>
  </joint>
  <link name="l_forearm_skin_10"/>
  <joint name="l_forearm_skin_10_fixed_joint" type="fixed">
    <origin xyz="0.0542285210888 0.007546 -0.0321469082866" rpy="-2.9412331340552202 -0.3283044719221903 -0.01396627819357275"/>
    <parent link="l_forearm"/>
    <child link="l_forearm_skin_10"/>
    <dynamics damping="0.1"/>
  </joint>
  <link name="l_forearm_skin_11"/>
  <joint name="l_forearm_skin_11_fixed_joint" type="fixed">
    <origin xyz="0.0542240912024 -0.0112832 -0.0321431259452" rpy="2.9392983595663433 -0.32910138974485226 0.01427348912915269"/>
    <parent link="l_forearm"/>
    <child link="l_forearm_skin_11"/>
    <dynamics damping="0.1"/>
  </joint>
  <link name="l_forearm_skin_12"/>
  <joint name="l_forearm_skin_12_fixed_joint" type="fixed">
    <origin xyz="0.0375994633868 -0.0204556 -0.0340191179961" rpy="2.5830350596406384 -0.2948305020697443 0.02132685044803456"/>
    <parent link="l_forearm"/>
    <child link="l_forearm_skin_12"/>
    <dynamics damping="0.1"/>
  </joint>
  <link name="l_forearm_skin_13"/>
  <joint name="l_forearm_skin_13_fixed_joint" type="fixed">
    <origin xyz="0.0228550868405 -0.0112878 -0.0418919009209" rpy="2.948966791979468 -0.2705839471887793 0.0017738500676491309"/>
    <parent link="l_forearm"/>
    <child link="l_forearm_skin_13"/>
    <dynamics damping="0.1"/>
  </joint>
  <link name="l_forearm_skin_14"/>
  <joint name="l_forearm_skin_14_fixed_joint" type="fixed">
    <origin xyz="0.0687703276364 -0.0193999 -0.0230239558511" rpy="2.5246225036344367 -0.3877945117708607 0.09129241116830253"/>
    <parent link="l_forearm"/>
    <child link="l_forearm_skin_14"/>
    <dynamics damping="0.1"/>
  </joint>
  <link name="l_forearm_skin_15"/>
  <joint name="l_forearm_skin_15_fixed_joint" type="fixed">
    <origin xyz="0.0633786419662 -0.0293843 -0.00879405455544" rpy="1.8049276974140638 -0.28978328191575403 0.11393373930609194"/>
    <parent link="l_forearm"/>
    <child link="l_forearm_skin_15"/>
    <dynamics damping="0.1"/>
  </joint>
  <link name="l_forearm_skin_16"/>
  <joint name="l_forearm_skin_16_fixed_joint" type="fixed">
    <origin xyz="0.03792482187 -0.0327268 0.0206369503605" rpy="1.4128000702560044 -0.25082462138972744 0.07586523015843158"/>
    <parent link="l_forearm"/>
    <child link="l_forearm_skin_16"/>
    <dynamics damping="0.1"/>
  </joint>
  <link name="l_forearm_skin_17"/>
  <joint name="l_forearm_skin_17_fixed_joint" type="fixed">
    <origin xyz="0.0543170548821 -0.0299646 0.0303291240179" rpy="1.2722371620529929 -0.23059304703026898 0.10963722521909765"/>
    <parent link="l_forearm"/>
    <child link="l_forearm_skin_17"/>
    <dynamics damping="0.1"/>
  </joint>
  <link name="l_forearm_skin_19"/>
  <joint name="l_forearm_skin_19_fixed_joint" type="fixed">
    <origin xyz="0.0381266107138 0.029054 0.020690605393" rpy="-1.415608887032208 -0.2525692902263517 -0.06444047470273734"/>
    <parent link="l_forearm"/>
    <child link="l_forearm_skin_19"/>
    <dynamics damping="0.1"/>
  </joint>
  <link name="l_forearm_skin_22"/>
  <joint name="l_forearm_skin_22_fixed_joint" type="fixed">
    <origin xyz="0.0544173950421 0.026483 0.0306037516609" rpy="-1.2658242727950597 -0.23432815137878313 -0.09370947388024636"/>
    <parent link="l_forearm"/>
    <child link="l_forearm_skin_22"/>
    <dynamics damping="0.1"/>
  </joint>
  <link name="l_forearm_skin_24"/>
  <joint name="l_forearm_skin_24_fixed_joint" type="fixed">
    <origin xyz="0.0700345319564 0.007477 0.050069108714" rpy="-0.23489327644017152 -0.038817299398176644 -0.054829198999867323"/>
    <parent link="l_forearm"/>
    <child link="l_forearm_skin_24"/>
    <dynamics damping="0.1"/>
  </joint>
  <link name="l_forearm_skin_25"/>
  <joint name="l_forearm_skin_25_fixed_joint" type="fixed">
    <origin xyz="0.0535999216295 0.015984 0.0454698125045" rpy="-0.5642955277146758 -0.1369802721974407 -0.08196082566558262"/>
    <parent link="l_forearm"/>
    <child link="l_forearm_skin_25"/>
    <dynamics damping="0.1"/>
  </joint>
  <link name="l_forearm_skin_28"/>
  <joint name="l_forearm_skin_28_fixed_joint" type="fixed">
    <origin xyz="0.0535859272148 -0.0196522 0.045352037397" rpy="0.5793111069492733 -0.13399430677809196 0.08675978583118527"/>
    <parent link="l_forearm"/>
    <child link="l_forearm_skin_28"/>
    <dynamics damping="0.1"/>
  </joint>
  <link name="l_forearm_skin_29"/>
  <joint name="l_forearm_skin_29_fixed_joint" type="fixed">
    <origin xyz="0.0700355805031 -0.0111936 0.0500111036233" rpy="0.24863098220864197 -0.03831365567858803 0.05830266242661145"/>
    <parent link="l_forearm"/>
    <child link="l_forearm_skin_29"/>
    <dynamics damping="0.1"/>
  </joint>
  <link name="l_forearm_dh_frame"/>
  <joint name="l_forearm_dh_frame_fixed_joint" type="fixed">
    <origin xyz="0.102871102373 7.00000000002e-06 0.0275642213111" rpy="2.879793333762637 0 1.5707963267948968"/>
    <parent link="l_forearm"/>
    <child link="l_forearm_dh_frame"/>
    <dynamics damping="0.1"/>
  </joint>
  <link name="l_wrist_1">
    <inertial>
      <origin xyz="-0.000981313804428 -0.001178 0.00408345773913" rpy="0 0 0"/>
      <mass value="0.0362152"/>
      <inertia ixx="5.56774e-06" ixy="3.08362e-08" ixz="9.42153e-07" iyy="5.28838e-06" iyz="-1.58924e-07" izz="1.87579e-06"/>
    </inertial>
    <visual>
      <origin xyz="-0.400314530555 -7.00000000009e-06 -0.105038082269" rpy="0 0 0"/>
      <geometry>
        <mesh filename="package://iCub/meshes/simmechanics/sim_sea_2-5_l_wrist_pitch_prt-binary.stl" scale="0.001 0.001 0.001"/>
      </geometry>
      <material name="dblue"/>
    </visual>
    <collision>
      <origin xyz="-0.400314530555 -7.00000000009e-06 -0.105038082269" rpy="0 0 0"/>
      <geometry>
        <mesh filename="package://iCub/meshes/simmechanics/sim_sea_2-5_l_wrist_pitch_prt-binary.stl" scale="0.001 0.001 0.001"/>
      </geometry>
    </collision>
  </link>
  <joint name="l_wrist_pitch" type="revolute">
    <origin xyz="0.103427563179 7.00000000002e-06 0.0254874807467" rpy="0 0 0"/>
    <axis xyz="0.258818979447 0.0 -0.965925843882"/>
    <parent link="l_forearm"/>
    <child link="l_wrist_1"/>
    <limit effort="50000" lower="-1.3962634015954636" upper="0.4363323129985824" velocity="50000"/>
    <dynamics damping="0.06"/>
  </joint>
  <link name="l_hand">
    <inertial>
      <origin xyz="0.0647680204057 0.0056304 0.0226602208449" rpy="0 0 0"/>
      <mass value="0.247806"/>
      <inertia ixx="0.000162491" ixy="2.96453e-06" ixz="-3.68906e-05" iyy="0.000430657" iyz="2.06885e-05" izz="0.000304729"/>
    </inertial>
    <visual>
      <origin xyz="-0.399680424055 0.0194929 -0.107404600587" rpy="0 0 0"/>
      <geometry>
        <mesh filename="package://iCub/meshes/simmechanics/sim_sea_2-5_l_hand_prt-binary.stl" scale="0.001 0.001 0.001"/>
      </geometry>
      <material name="dgreen"/>
    </visual>
    <collision>
      <origin xyz="-0.399680424055 0.0194929 -0.107404600587" rpy="0 0 0"/>
      <geometry>
        <mesh filename="package://iCub/meshes/simmechanics/sim_sea_2-5_l_hand_prt-binary.stl" scale="0.001 0.001 0.001"/>
      </geometry>
    </collision>
  </link>
  <joint name="l_wrist_yaw" type="revolute">
    <origin xyz="-0.000634106499644 -0.0194999 0.00236651831751" rpy="0 0 0"/>
    <axis xyz="-2.22044604925e-16 1.0 0.0"/>
    <parent link="l_wrist_1"/>
    <child link="l_hand"/>
    <limit effort="50000" lower="-0.3490658503988659" upper="0.4363323129985824" velocity="50000"/>
    <dynamics damping="0.06"/>
  </joint>
  <link name="l_hand_dh_frame"/>
  <joint name="l_hand_dh_frame_fixed_joint" type="fixed">
    <origin xyz="0.0576542978428 -0.0055568 0.0136938323083" rpy="-1.5707963267948963 -0.2617993198271562 0"/>
    <parent link="l_hand"/>
    <child link="l_hand_dh_frame"/>
    <dynamics damping="0.1"/>
  </joint>
  <link name="r_hip_1">
    <inertial>
      <origin xyz="-0.040711 -5.9e-05 -0.0005234" rpy="0 0 0"/>
      <mass value="0.920101"/>
      <inertia ixx="0.000411114" ixy="-3.6672e-06" ixz="3.58037e-07" iyy="0.000576521" iyz="-2.19976e-06" izz="0.000587325"/>
    </inertial>
    <visual>
      <origin xyz="0.0233655 0.151913 0.0428515000001" rpy="0 0 0"/>
      <geometry>
        <mesh filename="package://iCub/meshes/simmechanics/sim_sea_2-5_r_hip_1_prt-binary.stl" scale="0.001 0.001 0.001"/>
      </geometry>
      <material name="gray"/>
    </visual>
    <collision>
      <origin xyz="0.0233655 0.151913 0.0428515000001" rpy="0 0 0"/>
      <geometry>
        <mesh filename="package://iCub/meshes/simmechanics/sim_sea_2-5_r_hip_1_prt-binary.stl" scale="0.001 0.001 0.001"/>
      </geometry>
    </collision>
  </link>
  <joint name="r_hip_pitch" type="revolute">
    <origin xyz="0.0064515 0.0233655 -0.119913" rpy="1.5707963267948961 0 -1.5707963267948961"/>
    <axis xyz="-1.0 -0.0 -0.0"/>
    <parent link="root_link"/>
    <child link="r_hip_1"/>
    <limit effort="50000" lower="-0.5235987755982988" upper="1.4835298641951802" velocity="50000"/>
    <dynamics damping="0.223"/>
  </joint>
  <link name="r_hip_2">
    <inertial>
      <origin xyz="3.49999999999e-06 -0.044233 0.0248982" rpy="0 0 0"/>
      <mass value="0.4194"/>
      <inertia ixx="0.00048916" ixy="-2.70159e-07" ixz="1.85233e-07" iyy="0.00028697" iyz="1.28773e-05" izz="0.000315599"/>
    </inertial>
    <visual>
      <origin xyz="0.0701 0.151913 0.0691961998094" rpy="0 0 0"/>
      <geometry>
        <mesh filename="package://iCub/meshes/simmechanics/sim_sea_2-5_r_hip_2_prt-binary.stl" scale="0.001 0.001 0.001"/>
      </geometry>
      <material name="green"/>
    </visual>
    <collision>
      <origin xyz="0.0701 0.151913 0.0691961998094" rpy="0 0 0"/>
      <geometry>
        <mesh filename="package://iCub/meshes/simmechanics/sim_sea_2-5_r_hip_2_prt-binary.stl" scale="0.001 0.001 0.001"/>
      </geometry>
    </collision>
  </link>
  <joint name="r_hip_roll" type="revolute">
    <origin xyz="-0.0467345 0 -0.0263447" rpy="0 0 0"/>
    <axis xyz="-0.0 -0.0 -1.0"/>
    <parent link="r_hip_1"/>
    <child link="r_hip_2"/>
    <limit effort="50000" lower="0.0" upper="1.5707963267948966" velocity="50000"/>
    <dynamics damping="0.223"/>
  </joint>
  <link name="r_hip_3">
    <inertial>
      <origin xyz="-0.000123 -0.0002823 0.008718" rpy="-1.5707963267948961 0 -1.5707963267948961"/>
      <mass value="0.126212"/>
      <inertia ixx="3.27938e-05" ixy="2.67901e-07" ixz="-4.41463e-09" iyy="5.69957e-05" iyz="3.32338e-08" izz="3.26449e-05"/>
    </inertial>
    <visual>
      <origin xyz="0.0437089998094 -0.0701 -0.226213" rpy="-1.5707963267948961 0 -1.5707963267948961"/>
      <geometry>
        <mesh filename="package://iCub/meshes/simmechanics/sim_sea_2-5_r_upper_thigh_prt-binary.stl" scale="0.001 0.001 0.001"/>
      </geometry>
      <material name="black"/>
    </visual>
    <collision>
      <origin xyz="0.0437089998094 -0.0701 -0.226213" rpy="-1.5707963267948961 0 -1.5707963267948961"/>
      <geometry>
        <mesh filename="package://iCub/meshes/simmechanics/sim_sea_2-5_r_upper_thigh_prt-binary.stl" scale="0.001 0.001 0.001"/>
      </geometry>
    </collision>
  </link>
  <joint name="r_leg_ft_sensor" type="fixed">
    <origin xyz="0 -0.0743 0.0254872" rpy="1.5707963267948961 -1.570796326794896 0"/>
    <parent link="r_hip_2"/>
    <child link="r_hip_3"/>
    <dynamics damping="0.1"/>
  </joint>
  <link name="r_upper_leg">
    <inertial>
      <origin xyz="-7.67e-05 -0.078866 0.0033612" rpy="0 0 0"/>
      <mass value="1.8035"/>
      <inertia ixx="0.0064637834318241475" ixy="0.00012268585352168758" ixz="4.945315458683632e-06" iyy="0.0014453983221871295" iyz="-0.0001375331757178668" izz="0.006455826886182026"/>
    </inertial>
    <visual>
      <origin xyz="0.0701 0.241013 0.0437089998094" rpy="0 0 0"/>
      <geometry>
        <mesh filename="package://iCub/meshes/simmechanics/sim_sea_2-5_r_thigh_prt-binary.stl" scale="0.001 0.001 0.001"/>
      </geometry>
      <material name="red"/>
    </visual>
    <collision>
      <origin xyz="0.0701 0.241013 0.0437089998094" rpy="0 0 0"/>
      <geometry>
        <mesh filename="package://iCub/meshes/simmechanics/sim_sea_2-5_r_thigh_prt-binary.stl" scale="0.001 0.001 0.001"/>
      </geometry>
    </collision>
  </link>
  <joint name="r_hip_yaw" type="revolute">
    <origin xyz="0 0 0.0146" rpy="-1.5707963267948961 0 -1.5707963267948961"/>
    <axis xyz="0.0 -1.0 0.0"/>
    <parent link="r_hip_3"/>
    <child link="r_upper_leg"/>
    <limit effort="50000" lower="-1.2217304763960306" upper="1.2217304763960306" velocity="50000"/>
    <dynamics damping="0.223"/>
  </joint>
  <link name="r_upper_leg_ems_acc_eb8"/>
  <joint name="r_upper_leg_ems_acc_eb8_fixed_joint" type="fixed">
    <origin xyz="0.0404072 -0.040027 -0.0125751" rpy="1.5707963267948961 0 -1.5707963267948961"/>
    <parent link="r_upper_leg"/>
    <child link="r_upper_leg_ems_acc_eb8"/>
    <dynamics damping="0.1"/>
  </joint>
  <link name="r_upper_leg_ems_acc_eb11"/>
  <joint name="r_upper_leg_ems_acc_eb11_fixed_joint" type="fixed">
    <origin xyz="-0.040407 -0.083207 -0.0125771" rpy="1.5707963267948961 0 -1.5707963267948961"/>
    <parent link="r_upper_leg"/>
    <child link="r_upper_leg_ems_acc_eb11"/>
    <dynamics damping="0.1"/>
  </joint>
  <link name="r_upper_leg_ems_gyro_eb8"/>
  <joint name="r_upper_leg_ems_gyro_eb8_fixed_joint" type="fixed">
    <origin xyz="0.0404072 -0.035455 -0.013079" rpy="1.5707963267948961 0 -1.5707963267948961"/>
    <parent link="r_upper_leg"/>
    <child link="r_upper_leg_ems_gyro_eb8"/>
    <dynamics damping="0.1"/>
  </joint>
  <link name="r_upper_leg_ems_gyro_eb11"/>
  <joint name="r_upper_leg_ems_gyro_eb11_fixed_joint" type="fixed">
    <origin xyz="-0.040407 -0.087779 -0.013081" rpy="1.5707963267948961 0 -1.5707963267948961"/>
    <parent link="r_upper_leg"/>
    <child link="r_upper_leg_ems_gyro_eb11"/>
    <dynamics damping="0.1"/>
  </joint>
  <link name="r_upper_leg_mtb_acc_11b1"/>
  <joint name="r_upper_leg_mtb_acc_11b1_fixed_joint" type="fixed">
    <origin xyz="-0.030195 0.04914 0.043588612" rpy="-0.8377580538579834 -0.0003427907493437384 1.570874016517316"/>
    <parent link="r_upper_leg"/>
    <child link="r_upper_leg_mtb_acc_11b1"/>
    <dynamics damping="0.1"/>
  </joint>
  <link name="r_upper_leg_mtb_acc_11b2"/>
  <joint name="r_upper_leg_mtb_acc_11b2_fixed_joint" type="fixed">
    <origin xyz="-0.0064065 0.039256 0.0539467" rpy="-0.2617993419272076 -0.00039905013515403485 1.5709084831787057"/>
    <parent link="r_upper_leg"/>
    <child link="r_upper_leg_mtb_acc_11b2"/>
    <dynamics damping="0.1"/>
  </joint>
  <link name="r_upper_leg_mtb_acc_11b3"/>
  <joint name="r_upper_leg_mtb_acc_11b3_fixed_joint" type="fixed">
    <origin xyz="-0.0130214 0.004186 0.0538313" rpy="0 -0.00042908999059361946 1.570912443546613"/>
    <parent link="r_upper_leg"/>
    <child link="r_upper_leg_mtb_acc_11b3"/>
    <dynamics damping="0.1"/>
  </joint>
  <link name="r_upper_leg_mtb_acc_11b4"/>
  <joint name="r_upper_leg_mtb_acc_11b4_fixed_joint" type="fixed">
    <origin xyz="0.0422675 -0.004845 0.0322719" rpy="1.1868237508623853 -0.0005368537261927895 1.5708398310564209"/>
    <parent link="r_upper_leg"/>
    <child link="r_upper_leg_mtb_acc_11b4"/>
    <dynamics damping="0.1"/>
  </joint>
  <link name="r_upper_leg_mtb_acc_11b5"/>
  <joint name="r_upper_leg_mtb_acc_11b5_fixed_joint" type="fixed">
    <origin xyz="0.0164786 0.004186 0.0538313" rpy="0 -0.00042908999059361946 1.570912443546613"/>
    <parent link="r_upper_leg"/>
    <child link="r_upper_leg_mtb_acc_11b5"/>
    <dynamics damping="0.1"/>
  </joint>
  <link name="r_upper_leg_mtb_acc_11b6"/>
  <joint name="r_upper_leg_mtb_acc_11b6_fixed_joint" type="fixed">
    <origin xyz="-0.0157594 -0.026365 -0.0437518" rpy="3.141592653589793 0.0004290899934163925 -1.5707963267948968"/>
    <parent link="r_upper_leg"/>
    <child link="r_upper_leg_mtb_acc_11b6"/>
    <dynamics damping="0.1"/>
  </joint>
  <link name="r_upper_leg_mtb_acc_11b7"/>
  <joint name="r_upper_leg_mtb_acc_11b7_fixed_joint" type="fixed">
    <origin xyz="0.0162386 -0.026366 -0.0437518" rpy="3.1415926037711634 0.000429089990404397 -1.5709124300650796"/>
    <parent link="r_upper_leg"/>
    <child link="r_upper_leg_mtb_acc_11b7"/>
    <dynamics damping="0.1"/>
  </joint>
  <link name="r_lower_leg">
    <inertial>
      <origin xyz="0.0060664 -0.088843 0.0011052" rpy="0 0 0"/>
      <mass value="1.472"/>
      <inertia ixx="0.004242209336609336" ixy="0.00022953199017199019" ixz="-5.536062899262899e-05" iyy="0.0015122083538083536" iyz="-0.00026087390663390663" izz="0.004577651105651105"/>
    </inertial>
    <visual>
      <origin xyz="0.0797675001907 0.386638 0.0437089998093" rpy="0 0 0"/>
      <geometry>
        <mesh filename="package://iCub/meshes/simmechanics/sim_sea_2-5_r_shank_prt-binary.stl" scale="0.001 0.001 0.001"/>
      </geometry>
      <material name="blue"/>
    </visual>
    <collision>
      <origin xyz="0.0797675001907 0.386638 0.0437089998093" rpy="0 0 0"/>
      <geometry>
        <mesh filename="package://iCub/meshes/simmechanics/sim_sea_2-5_r_shank_prt-binary.stl" scale="0.001 0.001 0.001"/>
      </geometry>
    </collision>
  </link>
  <joint name="r_knee" type="revolute">
    <origin xyz="-0.0096675 -0.145625 0" rpy="0 0 0"/>
    <axis xyz="-1.0 -0.0 -0.0"/>
    <parent link="r_upper_leg"/>
    <child link="r_lower_leg"/>
    <limit effort="50000" lower="-1.7453292519943295" upper="0.0" velocity="50000"/>
    <dynamics damping="0.223"/>
  </joint>
  <link name="r_lower_leg_ems_acc_eb9"/>
  <joint name="r_lower_leg_ems_acc_eb9_fixed_joint" type="fixed">
    <origin xyz="0.0235071 -0.092765 0.04351373" rpy="0 -0.21816654334094113 1.5707963267948974"/>
    <parent link="r_lower_leg"/>
    <child link="r_lower_leg_ems_acc_eb9"/>
    <dynamics damping="0.1"/>
  </joint>
  <link name="r_lower_leg_ems_gyro_eb9"/>
  <joint name="r_lower_leg_ems_gyro_eb9_fixed_joint" type="fixed">
    <origin xyz="0.024011 -0.088301 0.044503292" rpy="0 -0.21816654334094113 1.5707963267948974"/>
    <parent link="r_lower_leg"/>
    <child link="r_lower_leg_ems_gyro_eb9"/>
    <dynamics damping="0.1"/>
  </joint>
  <link name="r_lower_leg_mtb_acc_11b8"/>
  <joint name="r_lower_leg_mtb_acc_11b8_fixed_joint" type="fixed">
    <origin xyz="-0.0055283 -0.004318 0.05362922" rpy="-0.24434616456547417 2.809110409620086e-05 1.570908994346253"/>
    <parent link="r_lower_leg"/>
    <child link="r_lower_leg_mtb_acc_11b8"/>
    <dynamics damping="0.1"/>
  </joint>
  <link name="r_lower_leg_mtb_acc_11b9"/>
  <joint name="r_lower_leg_mtb_acc_11b9_fixed_joint" type="fixed">
    <origin xyz="0.0253904 -0.004318 0.0537517" rpy="0.34906563804548707 -3.9714103784092166e-05 1.570905440483374"/>
    <parent link="r_lower_leg"/>
    <child link="r_lower_leg_mtb_acc_11b9"/>
    <dynamics damping="0.1"/>
  </joint>
  <link name="r_lower_leg_mtb_acc_11b10"/>
  <joint name="r_lower_leg_mtb_acc_11b10_fixed_joint" type="fixed">
    <origin xyz="-0.0325465 -0.043468 0.0278945" rpy="-1.3089971473150515 0 1.5707963267948972"/>
    <parent link="r_lower_leg"/>
    <child link="r_lower_leg_mtb_acc_11b10"/>
    <dynamics damping="0.1"/>
  </joint>
  <link name="r_lower_leg_mtb_acc_11b11"/>
  <joint name="r_lower_leg_mtb_acc_11b11_fixed_joint" type="fixed">
    <origin xyz="0.0519165 -0.092958 0.0164801" rpy="1.30899714593518 -0.00011215980287766697 1.5708263802148703"/>
    <parent link="r_lower_leg"/>
    <child link="r_lower_leg_mtb_acc_11b11"/>
    <dynamics damping="0.1"/>
  </joint>
  <link name="r_ankle_1">
    <inertial>
      <origin xyz="0.0276282 6.29999999999e-05 0.0152507" rpy="0 0 0"/>
      <mass value="0.6803"/>
      <inertia ixx="0.00040520108709481015" ixy="7.406015803200626e-07" ixz="-3.033146615806836e-05" iyy="0.00044910813662634846" iyz="2.889757259794077e-06" izz="0.0003100633505920521"/>
    </inertial>
    <visual>
      <origin xyz="0.0986000001907 0.587138 0.0437089998093" rpy="0 0 0"/>
      <geometry>
        <mesh filename="package://iCub/meshes/simmechanics/sim_sea_2-5_r_ankle_prt-binary.stl" scale="0.001 0.001 0.001"/>
      </geometry>
      <material name="yellow"/>
    </visual>
    <collision>
      <origin xyz="0.0986000001907 0.587138 0.0437089998093" rpy="0 0 0"/>
      <geometry>
        <mesh filename="package://iCub/meshes/simmechanics/sim_sea_2-5_r_ankle_prt-binary.stl" scale="0.001 0.001 0.001"/>
      </geometry>
    </collision>
  </link>
  <joint name="r_ankle_pitch" type="revolute">
    <origin xyz="-0.0188325 -0.2005 0" rpy="0 0 0"/>
    <axis xyz="1.0 0.0 0.0"/>
    <parent link="r_lower_leg"/>
    <child link="r_ankle_1"/>
    <limit effort="50000" lower="-0.3490658503988659" upper="0.5235987755982988" velocity="50000"/>
    <dynamics damping="0.223"/>
  </joint>
  <link name="r_ankle_2">
    <inertial>
      <origin xyz="-8.2e-06 -0.038202 0.0192673" rpy="0 0 0"/>
      <mass value="0.267485"/>
      <inertia ixx="0.000335682" ixy="-7.53335e-08" ixz="2.93681e-08" iyy="0.00025387" iyz="-4.26218e-07" izz="0.000154833"/>
    </inertial>
    <visual>
      <origin xyz="0.0701000001907 0.587138 0.0622089996185" rpy="0 0 0"/>
      <geometry>
        <mesh filename="package://iCub/meshes/simmechanics/sim_sea_2-5_r_foot_prt-binary.stl" scale="0.001 0.001 0.001"/>
      </geometry>
      <material name="pink"/>
    </visual>
    <collision>
      <origin xyz="0.0701000001907 0.587138 0.0622089996185" rpy="0 0 0"/>
      <geometry>
        <mesh filename="package://iCub/meshes/simmechanics/sim_sea_2-5_r_foot_prt-binary.stl" scale="0.001 0.001 0.001"/>
      </geometry>
    </collision>
  </link>
  <joint name="r_ankle_roll" type="revolute">
    <origin xyz="0.0285 0 -0.0185" rpy="0 0 0"/>
    <axis xyz="-0.0 -0.0 -1.0"/>
    <parent link="r_ankle_1"/>
    <child link="r_ankle_2"/>
    <limit effort="50000" lower="-0.3490658503988659" upper="0.3490658503988659" velocity="50000"/>
    <dynamics damping="0.223"/>
  </joint>
  <link name="r_foot">
    <inertial>
      <origin xyz="0.0336237 0.0053646 -0.001138" rpy="-1.5707963267948961 0 -1.5707963267948961"/>
      <mass value="0.38227"/>
      <inertia ixx="0.00120765" ixy="3.70545e-07" ixz="-5.78137e-05" iyy="0.00141242" iyz="-7.82502e-06" izz="0.000273419"/>
    </inertial>
    <visual>
      <origin xyz="0.0472089996185 -0.0701000001907 -0.647438" rpy="-1.5707963267948961 0 -1.5707963267948961"/>
      <geometry>
        <mesh filename="package://iCub/meshes/simmechanics/sim_sea_2-5_r_sole_prt-binary.stl" scale="0.001 0.001 0.001"/>
      </geometry>
      <material name="cyan"/>
    </visual>
    <collision>
      <origin xyz="0.0472089996185 -0.0701000001907 -0.647438" rpy="-1.5707963267948961 0 -1.5707963267948961"/>
      <geometry>
        <mesh filename="package://iCub/meshes/simmechanics/sim_sea_2-5_r_sole_prt-binary.stl" scale="0.001 0.001 0.001"/>
      </geometry>
    </collision>
  </link>
  <joint name="r_foot_ft_sensor" type="fixed">
    <origin xyz="0 -0.0603 0.015" rpy="1.5707963267948961 -1.570796326794896 0"/>
    <parent link="r_ankle_2"/>
    <child link="r_foot"/>
    <dynamics damping="0.1"/>
  </joint>
  <link name="r_foot_mtb_acc_11b12"/>
  <joint name="r_foot_mtb_acc_11b12_fixed_joint" type="fixed">
    <origin xyz="0.1034744 -0.000807 -0.001215" rpy="0 0 -1.5707963267948966"/>
    <parent link="r_foot"/>
    <child link="r_foot_mtb_acc_11b12"/>
    <dynamics damping="0.1"/>
  </joint>
  <link name="r_foot_mtb_acc_11b13"/>
  <joint name="r_foot_mtb_acc_11b13_fixed_joint" type="fixed">
    <origin xyz="0.0784744 -0.0118072 -0.001215" rpy="0 0 -1.5707963267948966"/>
    <parent link="r_foot"/>
    <child link="r_foot_mtb_acc_11b13"/>
    <dynamics damping="0.1"/>
  </joint>
  <link name="r_sole"/>
  <joint name="r_sole_fixed_joint" type="fixed">
    <origin xyz="0.0035 0 0.004" rpy="-3.141592653589793 0 0"/>
    <parent link="r_foot"/>
    <child link="r_sole"/>
    <dynamics damping="0.1"/>
  </joint>
  <link name="l_hip_1">
    <inertial>
      <origin xyz="0.041678 -6.3e-05 -0.0004013" rpy="0 0 0"/>
      <mass value="0.915608"/>
      <inertia ixx="0.000402555" ixy="1.07708e-06" ixz="-1.569e-06" iyy="0.000570806" iyz="-6.5378e-07" izz="0.00057937"/>
    </inertial>
    <visual>
      <origin xyz="-0.0223861 0.151913 0.0428515000001" rpy="0 0 0"/>
      <geometry>
        <mesh filename="package://iCub/meshes/simmechanics/sim_sea_2-5_l_hip_1_prt-binary.stl" scale="0.001 0.001 0.001"/>
      </geometry>
      <material name="green"/>
    </visual>
    <collision>
      <origin xyz="-0.0223861 0.151913 0.0428515000001" rpy="0 0 0"/>
      <geometry>
        <mesh filename="package://iCub/meshes/simmechanics/sim_sea_2-5_l_hip_1_prt-binary.stl" scale="0.001 0.001 0.001"/>
      </geometry>
    </collision>
  </link>
  <joint name="l_hip_pitch" type="revolute">
    <origin xyz="0.0064515 -0.0223861 -0.119913" rpy="1.5707963267948961 0 -1.5707963267948961"/>
    <axis xyz="-1.0 0.0 0.0"/>
    <parent link="root_link"/>
    <child link="l_hip_1"/>
    <limit effort="50000" lower="-0.5235987755982988" upper="1.4835298641951802" velocity="50000"/>
    <dynamics damping="0.223"/>
  </joint>
  <link name="l_hip_2">
    <inertial>
      <origin xyz="-1.94e-05 -0.044047 0.0239587" rpy="0 0 0"/>
      <mass value="0.421161"/>
      <inertia ixx="0.000494475" ixy="1.54783e-07" ixz="-1.86267e-07" iyy="0.000288821" iyz="1.53903e-05" izz="0.000319114"/>
    </inertial>
    <visual>
      <origin xyz="-0.0701 0.151913 0.0683914998093" rpy="0 0 0"/>
      <geometry>
        <mesh filename="package://iCub/meshes/simmechanics/sim_sea_2-5_l_hip_2_prt-binary.stl" scale="0.001 0.001 0.001"/>
      </geometry>
      <material name="white"/>
    </visual>
    <collision>
      <origin xyz="-0.0701 0.151913 0.0683914998093" rpy="0 0 0"/>
      <geometry>
        <mesh filename="package://iCub/meshes/simmechanics/sim_sea_2-5_l_hip_2_prt-binary.stl" scale="0.001 0.001 0.001"/>
      </geometry>
    </collision>
  </link>
  <joint name="l_hip_roll" type="revolute">
    <origin xyz="0.0477139 0 -0.02554" rpy="0 0 0"/>
    <axis xyz="0.0 0.0 1.0"/>
    <parent link="l_hip_1"/>
    <child link="l_hip_2"/>
    <limit effort="50000" lower="0.0" upper="1.5707963267948966" velocity="50000"/>
    <dynamics damping="0.223"/>
  </joint>
  <link name="l_hip_3">
    <inertial>
      <origin xyz="0.0002823 -0.0001229 0.008718" rpy="-1.5707963267948966 0 0"/>
      <mass value="0.126212"/>
      <inertia ixx="3.27938e-05" ixy="2.67901e-07" ixz="-4.41463e-09" iyy="5.69957e-05" iyz="3.32338e-08" izz="3.26449e-05"/>
    </inertial>
    <visual>
      <origin xyz="-0.0701 0.043709 -0.226213" rpy="-1.5707963267948966 0 0"/>
      <geometry>
        <mesh filename="package://iCub/meshes/simmechanics/sim_sea_2-5_l_upper_thigh_prt-binary.stl" scale="0.001 0.001 0.001"/>
      </geometry>
      <material name="dblue"/>
    </visual>
    <collision>
      <origin xyz="-0.0701 0.043709 -0.226213" rpy="-1.5707963267948966 0 0"/>
      <geometry>
        <mesh filename="package://iCub/meshes/simmechanics/sim_sea_2-5_l_upper_thigh_prt-binary.stl" scale="0.001 0.001 0.001"/>
      </geometry>
    </collision>
  </link>
  <joint name="l_leg_ft_sensor" type="fixed">
    <origin xyz="0 -0.0743 0.0246825" rpy="1.5707963267948961 -1.570796326794896 0"/>
    <parent link="l_hip_2"/>
    <child link="l_hip_3"/>
    <dynamics damping="0.1"/>
  </joint>
  <link name="l_upper_leg">
    <inertial>
      <origin xyz="0.0001504 -0.078827 0.0033485" rpy="0 0 0"/>
      <mass value="1.8084"/>
      <inertia ixx="0.006471240657182458" ixy="-0.00011751076946693093" ixz="-3.5729475798113695e-06" iyy="0.0014484362127580805" iyz="-0.00013770851980441645" izz="0.0064646436071894575"/>
    </inertial>
    <visual>
      <origin xyz="-0.0701 0.241013 0.0437089998093" rpy="0 0 0"/>
      <geometry>
        <mesh filename="package://iCub/meshes/simmechanics/sim_sea_2-5_l_thigh_prt-binary.stl" scale="0.001 0.001 0.001"/>
      </geometry>
      <material name="dgreen"/>
    </visual>
    <collision>
      <origin xyz="-0.0701 0.241013 0.0437089998093" rpy="0 0 0"/>
      <geometry>
        <mesh filename="package://iCub/meshes/simmechanics/sim_sea_2-5_l_thigh_prt-binary.stl" scale="0.001 0.001 0.001"/>
      </geometry>
    </collision>
  </link>
  <joint name="l_hip_yaw" type="revolute">
    <origin xyz="0 0 0.0146" rpy="-1.5707963267948961 0 -1.5707963267948961"/>
    <axis xyz="0.0 1.0 0.0"/>
    <parent link="l_hip_3"/>
    <child link="l_upper_leg"/>
    <limit effort="50000" lower="-1.2217304763960306" upper="1.2217304763960306" velocity="50000"/>
    <dynamics damping="0.223"/>
  </joint>
  <link name="l_upper_leg_ems_acc_eb6"/>
  <joint name="l_upper_leg_ems_acc_eb6_fixed_joint" type="fixed">
    <origin xyz="-0.0404072 -0.083207 -0.0125771" rpy="1.5707963267948961 0 -1.5707963267948961"/>
    <parent link="l_upper_leg"/>
    <child link="l_upper_leg_ems_acc_eb6"/>
    <dynamics damping="0.1"/>
  </joint>
  <link name="l_upper_leg_ems_acc_eb10"/>
  <joint name="l_upper_leg_ems_acc_eb10_fixed_joint" type="fixed">
    <origin xyz="0.040407 -0.040027 -0.0125751" rpy="1.5707963267948961 0 1.5707963267948961"/>
    <parent link="l_upper_leg"/>
    <child link="l_upper_leg_ems_acc_eb10"/>
    <dynamics damping="0.1"/>
  </joint>
  <link name="l_upper_leg_ems_gyro_eb6"/>
  <joint name="l_upper_leg_ems_gyro_eb6_fixed_joint" type="fixed">
    <origin xyz="-0.0404072 -0.087779 -0.013081" rpy="1.5707963267948961 0 -1.5707963267948961"/>
    <parent link="l_upper_leg"/>
    <child link="l_upper_leg_ems_gyro_eb6"/>
    <dynamics damping="0.1"/>
  </joint>
  <link name="l_upper_leg_ems_gyro_eb10"/>
  <joint name="l_upper_leg_ems_gyro_eb10_fixed_joint" type="fixed">
    <origin xyz="0.040407 -0.035455 -0.013079" rpy="1.5707963267948961 0 1.5707963267948961"/>
    <parent link="l_upper_leg"/>
    <child link="l_upper_leg_ems_gyro_eb10"/>
    <dynamics damping="0.1"/>
  </joint>
  <link name="l_upper_leg_mtb_acc_10b1"/>
  <joint name="l_upper_leg_mtb_acc_10b1_fixed_joint" type="fixed">
    <origin xyz="0.031565 0.049332 0.04200163" rpy="0.8377580369611063 -8.629128296528757e-05 1.5708740239417243"/>
    <parent link="l_upper_leg"/>
    <child link="l_upper_leg_mtb_acc_10b1"/>
    <dynamics damping="0.1"/>
  </joint>
  <link name="l_upper_leg_mtb_acc_10b2"/>
  <joint name="l_upper_leg_mtb_acc_10b2_fixed_joint" type="fixed">
    <origin xyz="0.0083839 0.039452 0.05335544" rpy="0.26179931813486096 -3.00531353284448e-05 1.5709084866269047"/>
    <parent link="l_upper_leg"/>
    <child link="l_upper_leg_mtb_acc_10b2"/>
    <dynamics damping="0.1"/>
  </joint>
  <link name="l_upper_leg_mtb_acc_10b3"/>
  <joint name="l_upper_leg_mtb_acc_10b3_fixed_joint" type="fixed">
    <origin xyz="0.0150706 0.004382 0.053785" rpy="0 0 1.5707963267948966"/>
    <parent link="l_upper_leg"/>
    <child link="l_upper_leg_mtb_acc_10b3"/>
    <dynamics damping="0.1"/>
  </joint>
  <link name="l_upper_leg_mtb_acc_10b4"/>
  <joint name="l_upper_leg_mtb_acc_10b4_fixed_joint" type="fixed">
    <origin xyz="-0.0144294 0.004382 0.053785" rpy="0 0 1.5707963267948966"/>
    <parent link="l_upper_leg"/>
    <child link="l_upper_leg_mtb_acc_10b4"/>
    <dynamics damping="0.1"/>
  </joint>
  <link name="l_upper_leg_mtb_acc_10b5"/>
  <joint name="l_upper_leg_mtb_acc_10b5_fixed_joint" type="fixed">
    <origin xyz="-0.0414999 -0.004658 0.03412949" rpy="-1.186823762544959 0 1.5707963267948963"/>
    <parent link="l_upper_leg"/>
    <child link="l_upper_leg_mtb_acc_10b5"/>
    <dynamics damping="0.1"/>
  </joint>
  <link name="l_upper_leg_mtb_acc_10b6"/>
  <joint name="l_upper_leg_mtb_acc_10b6_fixed_joint" type="fixed">
    <origin xyz="0.0178086 -0.026212 -0.043785" rpy="3.141592653589793 0 -1.5709124300543913"/>
    <parent link="l_upper_leg"/>
    <child link="l_upper_leg_mtb_acc_10b6"/>
    <dynamics damping="0.1"/>
  </joint>
  <link name="l_upper_leg_mtb_acc_10b7"/>
  <joint name="l_upper_leg_mtb_acc_10b7_fixed_joint" type="fixed">
    <origin xyz="-0.0141918 -0.026211 -0.043785" rpy="3.141592653589793 0 -1.5709453146950971"/>
    <parent link="l_upper_leg"/>
    <child link="l_upper_leg_mtb_acc_10b7"/>
    <dynamics damping="0.1"/>
  </joint>
  <link name="l_lower_leg">
    <inertial>
      <origin xyz="0.0171669 -0.088615 0.000868" rpy="0 0 0"/>
      <mass value="1.4724"/>
      <inertia ixx="0.004239347019337061" ixy="-0.0002400909088578798" ixz="6.757548336243771e-05" iyy="0.0015134133581121132" iyz="-0.00022978724619106362" izz="0.004574200330027716"/>
    </inertial>
    <visual>
      <origin xyz="-0.0565145001907 0.386638 0.0437089998093" rpy="0 0 0"/>
      <geometry>
        <mesh filename="package://iCub/meshes/simmechanics/sim_sea_2-5_l_shank_prt-binary.stl" scale="0.001 0.001 0.001"/>
      </geometry>
      <material name="gray"/>
    </visual>
    <collision>
      <origin xyz="-0.0565145001907 0.386638 0.0437089998093" rpy="0 0 0"/>
      <geometry>
        <mesh filename="package://iCub/meshes/simmechanics/sim_sea_2-5_l_shank_prt-binary.stl" scale="0.001 0.001 0.001"/>
      </geometry>
    </collision>
  </link>
  <joint name="l_knee" type="revolute">
    <origin xyz="-0.0135855 -0.145625 0" rpy="0 0 0"/>
    <axis xyz="-1.0 0.0 0.0"/>
    <parent link="l_upper_leg"/>
    <child link="l_lower_leg"/>
    <limit effort="50000" lower="-1.7453292519943295" upper="0.0" velocity="50000"/>
    <dynamics damping="0.223"/>
  </joint>
  <link name="l_lower_leg_ems_acc_eb7"/>
  <joint name="l_lower_leg_ems_acc_eb7_fixed_joint" type="fixed">
    <origin xyz="0.0249001 -0.092765 0.04351373" rpy="0 -0.21816654334094113 1.5707963267948974"/>
    <parent link="l_lower_leg"/>
    <child link="l_lower_leg_ems_acc_eb7"/>
    <dynamics damping="0.1"/>
  </joint>
  <link name="l_lower_leg_ems_gyro_eb7"/>
  <joint name="l_lower_leg_ems_gyro_eb7_fixed_joint" type="fixed">
    <origin xyz="0.025404 -0.088301 0.044503292" rpy="0 -0.21816654334094113 1.5707963267948974"/>
    <parent link="l_lower_leg"/>
    <child link="l_lower_leg_ems_gyro_eb7"/>
    <dynamics damping="0.1"/>
  </joint>
  <link name="l_lower_leg_mtb_acc_10b8"/>
  <joint name="l_lower_leg_mtb_acc_10b8_fixed_joint" type="fixed">
    <origin xyz="0.0307696 -0.004318 0.05313347" rpy="0.24434616607044674 0 1.5707963267948972"/>
    <parent link="l_lower_leg"/>
    <child link="l_lower_leg_mtb_acc_10b8"/>
    <dynamics damping="0.1"/>
  </joint>
  <link name="l_lower_leg_mtb_acc_10b9"/>
  <joint name="l_lower_leg_mtb_acc_10b9_fixed_joint" type="fixed">
    <origin xyz="-0.0002136 -0.004318 0.0544518" rpy="-0.34906563804548707 3.9714103784092166e-05 1.570905440483374"/>
    <parent link="l_lower_leg"/>
    <child link="l_lower_leg_mtb_acc_10b9"/>
    <dynamics damping="0.1"/>
  </joint>
  <link name="l_lower_leg_mtb_acc_10b10"/>
  <joint name="l_lower_leg_mtb_acc_10b10_fixed_joint" type="fixed">
    <origin xyz="0.0563295 -0.043468 0.0259151" rpy="1.30899714593518 -0.00011215980287766697 1.5708263802148703"/>
    <parent link="l_lower_leg"/>
    <child link="l_lower_leg_mtb_acc_10b10"/>
    <dynamics damping="0.1"/>
  </joint>
  <link name="l_lower_leg_mtb_acc_10b11"/>
  <joint name="l_lower_leg_mtb_acc_10b11_fixed_joint" type="fixed">
    <origin xyz="-0.0281332 -0.092958 0.0184593" rpy="-1.3089971472018722 -2.543178857158298e-05 1.5707895123459004"/>
    <parent link="l_lower_leg"/>
    <child link="l_lower_leg_mtb_acc_10b11"/>
    <dynamics damping="0.1"/>
  </joint>
  <link name="l_ankle_1">
    <inertial>
      <origin xyz="-0.0261116 6.29999999999e-05 0.0152606" rpy="0 0 0"/>
      <mass value="0.6798"/>
      <inertia ixx="0.0004050612993573232" ixy="-1.125154392457926e-06" ixz="3.067637700367601e-05" iyy="0.0004483455625296957" iyz="2.889929280552152e-06" izz="0.0003094157193228137"/>
    </inertial>
    <visual>
      <origin xyz="-0.0971179001907 0.587138 0.043409" rpy="0 0 0"/>
      <geometry>
        <mesh filename="package://iCub/meshes/simmechanics/sim_sea_2-5_l_ankle_prt-binary.stl" scale="0.001 0.001 0.001"/>
      </geometry>
      <material name="green"/>
    </visual>
    <collision>
      <origin xyz="-0.0971179001907 0.587138 0.043409" rpy="0 0 0"/>
      <geometry>
        <mesh filename="package://iCub/meshes/simmechanics/sim_sea_2-5_l_ankle_prt-binary.stl" scale="0.001 0.001 0.001"/>
      </geometry>
    </collision>
  </link>
  <joint name="l_ankle_pitch" type="revolute">
    <origin xyz="0.0406034 -0.2005 0" rpy="0 0 0"/>
    <axis xyz="1.0 0.0 0.0"/>
    <parent link="l_lower_leg"/>
    <child link="l_ankle_1"/>
    <limit effort="50000" lower="-0.3490658503988659" upper="0.5235987755982988" velocity="50000"/>
    <dynamics damping="0.223"/>
  </joint>
  <link name="l_ankle_2">
    <inertial>
      <origin xyz="-8.19999999999e-06 -0.038202 -0.04732025" rpy="0 0 0"/>
      <mass value="0.267485"/>
      <inertia ixx="0.000335682" ixy="-7.53335e-08" ixz="2.93681e-08" iyy="0.00025387" iyz="-4.26218e-07" izz="0.000154833"/>
    </inertial>
    <visual>
      <origin xyz="-0.0701000001907 0.587138 -0.00467855" rpy="0 0 0"/>
      <geometry>
        <mesh filename="package://iCub/meshes/simmechanics/sim_sea_2-5_l_foot_prt-binary.stl" scale="0.001 0.001 0.001"/>
      </geometry>
      <material name="black"/>
    </visual>
    <collision>
      <origin xyz="-0.0701000001907 0.587138 -0.00467855" rpy="0 0 0"/>
      <geometry>
        <mesh filename="package://iCub/meshes/simmechanics/sim_sea_2-5_l_foot_prt-binary.stl" scale="0.001 0.001 0.001"/>
      </geometry>
    </collision>
  </link>
  <joint name="l_ankle_roll" type="revolute">
    <origin xyz="-0.0270179 0 0.04808755" rpy="0 0 0"/>
    <axis xyz="0.0 0.0 1.0"/>
    <parent link="l_ankle_1"/>
    <child link="l_ankle_2"/>
    <limit effort="50000" lower="-0.3490658503988659" upper="0.3490658503988659" velocity="50000"/>
    <dynamics damping="0.223"/>
  </joint>
  <link name="l_foot">
    <inertial>
      <origin xyz="0.0336906 -0.0053662 -0.001154" rpy="-1.5707963267948961 0 -1.5707963267948961"/>
      <mass value="0.382372"/>
      <inertia ixx="0.00121061" ixy="-3.65345e-07" ixz="5.78649e-05" iyy="0.00141515" iyz="-7.67241e-06" izz="0.000273665"/>
    </inertial>
    <visual>
      <origin xyz="0.0472089996187 0.0701000001907 -0.647438" rpy="-1.5707963267948961 0 -1.5707963267948961"/>
      <geometry>
        <mesh filename="package://iCub/meshes/simmechanics/sim_sea_2-5_l_sole_prt-binary.stl" scale="0.001 0.001 0.001"/>
      </geometry>
      <material name="red"/>
    </visual>
    <collision>
      <origin xyz="0.0472089996187 0.0701000001907 -0.647438" rpy="-1.5707963267948961 0 -1.5707963267948961"/>
      <geometry>
        <mesh filename="package://iCub/meshes/simmechanics/sim_sea_2-5_l_sole_prt-binary.stl" scale="0.001 0.001 0.001"/>
      </geometry>
    </collision>
  </link>
  <joint name="l_foot_ft_sensor" type="fixed">
    <origin xyz="0 -0.0603 -0.05158755" rpy="1.5707963267948961 -1.570796326794896 0"/>
    <parent link="l_ankle_2"/>
    <child link="l_foot"/>
    <dynamics damping="0.1"/>
  </joint>
  <link name="l_foot_mtb_acc_10b12"/>
  <joint name="l_foot_mtb_acc_10b12_fixed_joint" type="fixed">
    <origin xyz="0.1055224 0.0008072 -0.001215" rpy="0 0 1.5707963267948966"/>
    <parent link="l_foot"/>
    <child link="l_foot_mtb_acc_10b12"/>
    <dynamics damping="0.1"/>
  </joint>
  <link name="l_foot_mtb_acc_10b13"/>
  <joint name="l_foot_mtb_acc_10b13_fixed_joint" type="fixed">
    <origin xyz="0.0805224 0.0118072 -0.001215" rpy="0 0 1.5707963267948966"/>
    <parent link="l_foot"/>
    <child link="l_foot_mtb_acc_10b13"/>
    <dynamics damping="0.1"/>
  </joint>
  <link name="l_sole"/>
  <joint name="l_sole_fixed_joint" type="fixed">
    <origin xyz="0.0035 0 0.004" rpy="-3.141592653589793 0 0"/>
    <parent link="l_foot"/>
    <child link="l_sole"/>
    <dynamics damping="0.1"/>
  </joint>
  <gazebo reference="l_leg_ft_sensor">
    <sensor name="l_leg_ft_sensor" type="force_torque">
      <always_on>1</always_on>
      <update_rate>100</update_rate>
      <force_torque>
        <frame>child</frame>
        <measure_direction>child_to_parent</measure_direction>
      </force_torque>
    </sensor>
  </gazebo>
  <sensor name="l_leg_ft_sensor" type="force_torque">
    <parent joint="l_leg_ft_sensor"/>
    <force_torque>
      <frame>child</frame>
      <measure_direction>child_to_parent</measure_direction>
    </force_torque>
  </sensor>
  <gazebo reference="r_leg_ft_sensor">
    <sensor name="r_leg_ft_sensor" type="force_torque">
      <always_on>1</always_on>
      <update_rate>100</update_rate>
      <force_torque>
        <frame>child</frame>
        <measure_direction>child_to_parent</measure_direction>
      </force_torque>
    </sensor>
  </gazebo>
  <sensor name="r_leg_ft_sensor" type="force_torque">
    <parent joint="r_leg_ft_sensor"/>
    <force_torque>
      <frame>child</frame>
      <measure_direction>child_to_parent</measure_direction>
    </force_torque>
  </sensor>
  <gazebo reference="l_foot_ft_sensor">
    <sensor name="l_foot_ft_sensor" type="force_torque">
      <always_on>1</always_on>
      <update_rate>100</update_rate>
      <force_torque>
        <frame>child</frame>
        <measure_direction>child_to_parent</measure_direction>
      </force_torque>
    </sensor>
  </gazebo>
  <sensor name="l_foot_ft_sensor" type="force_torque">
    <parent joint="l_foot_ft_sensor"/>
    <force_torque>
      <frame>child</frame>
      <measure_direction>child_to_parent</measure_direction>
    </force_torque>
  </sensor>
  <gazebo reference="r_foot_ft_sensor">
    <sensor name="r_foot_ft_sensor" type="force_torque">
      <always_on>1</always_on>
      <update_rate>100</update_rate>
      <force_torque>
        <frame>child</frame>
        <measure_direction>child_to_parent</measure_direction>
      </force_torque>
    </sensor>
  </gazebo>
  <sensor name="r_foot_ft_sensor" type="force_torque">
    <parent joint="r_foot_ft_sensor"/>
    <force_torque>
      <frame>child</frame>
      <measure_direction>child_to_parent</measure_direction>
    </force_torque>
  </sensor>
  <gazebo reference="l_arm_ft_sensor">
    <sensor name="l_arm_ft_sensor" type="force_torque">
      <always_on>1</always_on>
      <update_rate>100</update_rate>
      <force_torque>
        <frame>child</frame>
        <measure_direction>child_to_parent</measure_direction>
      </force_torque>
    </sensor>
  </gazebo>
  <sensor name="l_arm_ft_sensor" type="force_torque">
    <parent joint="l_arm_ft_sensor"/>
    <force_torque>
      <frame>child</frame>
      <measure_direction>child_to_parent</measure_direction>
    </force_torque>
  </sensor>
  <gazebo reference="r_arm_ft_sensor">
    <sensor name="r_arm_ft_sensor" type="force_torque">
      <always_on>1</always_on>
      <update_rate>100</update_rate>
      <force_torque>
        <frame>child</frame>
        <measure_direction>child_to_parent</measure_direction>
      </force_torque>
    </sensor>
  </gazebo>
  <sensor name="r_arm_ft_sensor" type="force_torque">
    <parent joint="r_arm_ft_sensor"/>
    <force_torque>
      <frame>child</frame>
      <measure_direction>child_to_parent</measure_direction>
    </force_torque>
  </sensor>
  <gazebo reference="head">
    <sensor name="imu_frame" type="imu">
      <always_on>1</always_on>
      <update_rate>100</update_rate>
      <pose>0.00950000019074 0.133444 0.0093 -1.5707963267948963 1.5707963267948963 0.0</pose>
    </sensor>
  </gazebo>
  <sensor name="imu_frame" type="imu">
    <parent link="head"/>
    <origin rpy="-1.5707963267948963 1.5707963267948963 0.0" xyz="0.00950000019074 0.133444 0.0093"/>
  </sensor>
  <link name="base_link"/>
  <joint name="base_fixed_joint" type="fixed">
  <origin xyz="0 0 0" rpy="0 -0 0"/>
  <axis xyz="0 0 0"/>
  <parent link="base_link"/>
  <child link="root_link"/>
</joint>
  <link name="l_foot_dh_frame"/>
  <joint name="l_foot_dh_frame_fixed_joint" type="fixed">
  <origin xyz="0.0 0 0.004" rpy="0 1.5708 0"/>
  <axis xyz="0 0 0"/>
  <parent link="l_foot"/>
  <child link="l_foot_dh_frame"/>
</joint>
  <link name="r_foot_dh_frame"/>
  <joint name="r_foot_dh_frame_fixed_joint" type="fixed">
  <origin xyz="0.0 0 0.004" rpy="0 1.5708 0"/>
  <axis xyz="0 0 0"/>
  <parent link="r_foot"/>
  <child link="r_foot_dh_frame"/>
</joint>
  <gazebo reference="r_arm_ft_sensor">
  <disableFixedJointLumping>true</disableFixedJointLumping>
</gazebo>
  <gazebo reference="r_arm_ft_sensor">
  <disableFixedJointLumping>true</disableFixedJointLumping>
</gazebo>
  <gazebo reference="l_arm_ft_sensor">
  <disableFixedJointLumping>true</disableFixedJointLumping>
</gazebo>
  <gazebo reference="r_leg_ft_sensor">
  <disableFixedJointLumping>true</disableFixedJointLumping>
</gazebo>
  <gazebo reference="l_leg_ft_sensor">
  <disableFixedJointLumping>true</disableFixedJointLumping>
</gazebo>
  <gazebo reference="r_foot_ft_sensor">
  <disableFixedJointLumping>true</disableFixedJointLumping>
</gazebo>
  <gazebo reference="l_foot_ft_sensor">
  <disableFixedJointLumping>true</disableFixedJointLumping>
</gazebo>
  <gazebo>
<plugin name="controlboard_torso" filename="libgazebo_yarp_controlboard.so">
    <yarpConfigurationFile>model://iCubGenova02/conf/gazebo_iCubGenova02_torso.ini</yarpConfigurationFile>
</plugin>
<plugin name="controlboard_head" filename="libgazebo_yarp_controlboard.so">
    <yarpConfigurationFile>model://iCubGenova02/conf/gazebo_iCubGenova02_head.ini</yarpConfigurationFile>
</plugin>
<plugin name="controlboard_left_arm" filename="libgazebo_yarp_controlboard.so">
    <yarpConfigurationFile>model://iCubGenova02/conf/gazebo_iCubGenova02_left_arm.ini</yarpConfigurationFile>
    <initialConfiguration>-0.52 0.52 0 0.785 0 0 0.698</initialConfiguration>
</plugin>
<plugin name="controlboard_right_arm" filename="libgazebo_yarp_controlboard.so">
    <yarpConfigurationFile>model://iCubGenova02/conf/gazebo_iCubGenova02_right_arm.ini</yarpConfigurationFile>
    <initialConfiguration>-0.52 0.52 0 0.785 0 0 0.698</initialConfiguration>
</plugin>
<plugin name="controlboard_right_leg" filename="libgazebo_yarp_controlboard.so">
    <yarpConfigurationFile>model://iCubGenova02/conf/gazebo_iCubGenova02_right_leg.ini</yarpConfigurationFile>
</plugin>
<plugin name="controlboard_left_leg" filename="libgazebo_yarp_controlboard.so">
    <yarpConfigurationFile>model://iCubGenova02/conf/gazebo_iCubGenova02_left_leg.ini</yarpConfigurationFile>
</plugin>
<plugin name="apply_external_wrench" filename="libgazebo_yarp_externalwrench.so">
     <robotNamefromConfigFile>model://iCubGenova02/conf/gazebo_iCubGenova02_robotname.ini</robotNamefromConfigFile>
</plugin>
</gazebo>
</robot>
